Workbook
Name eredmeny: '15. kör sorsolás'!$L$3:$L$11
Name nevezettek: Ligabeosztas!$A$1:$D$287

Sheet A liga
B1: =VLOOKUP(CONCATENATE(LEFT($A$2,1),COLUMN()-1),nevezettek,3,FALSE) -> Marton Zoltán | C1: =VLOOKUP(CONCATENATE(LEFT($A$2,1),COLUMN()-1),nevezettek,3,FALSE) -> Tóth Zoltán | D1: =VLOOKUP(CONCATENATE(LEFT($A$2,1),COLUMN()-1),nevezettek,3,FALSE) -> Polgár István | E1: =VLOOKUP(CONCATENATE(LEFT($A$2,1),COLUMN()-1),nevezettek,3,FALSE) -> Weisz György | F1: =VLOOKUP(CONCATENATE(LEFT($A$2,1),COLUMN()-1),nevezettek,3,FALSE) -> Nagy Ferenc | G1: =VLOOKUP(CONCATENATE(LEFT($A$2,1),COLUMN()-1),nevezettek,3,FALSE) -> Dombay Miklós | H1: =VLOOKUP(CONCATENATE(LEFT($A$2,1),COLUMN()-1),nevezettek,3,FALSE) -> Pék Róbert | I1: =VLOOKUP(CONCATENATE(LEFT($A$2,1),COLUMN()-1),nevezettek,3,FALSE) -> Kovács Gábor | ... K1: =VLOOKUP(CONCATENATE(LEFT($A$2,1),COLUMN()-1),nevezettek,3,FALSE) -> 0 | L1: összpont-szám | M1: Győze-lem | N1: Nyert szett | O1: Vesztett szett | P1: helyezés (hatékonyság)
A2: =RIGHT(CELL("filename",A1),6) -> A liga
A3: =COUNTIF(Ligabeosztas!D:D,LEFT(A2,1)) -> 10
A4: =B1 -> Marton Zoltán | L4: =5*(COUNTIF(B4:K6,"5/0")+COUNTIF(B4:K6,"4/1")+COUNTIF(B4:K6,"3/2")+COUNTIF(B4:K6,"5/-"))+3*COUNTIF(B4:K6,"2/3")+2*COUNTIF(B4:K6,"1/4")+COUNTIF(B4:K6,"0/5")+0.01*M4+0.0001*(N4) -> 0 | M4: =1*COUNTIF(B4:K6,"5/0")+1*COUNTIF(B4:K6,"4/1")+1*COUNTIF(B4:K6,"3/2")+1*COUNTIF(B4:K6,"5/-")+0*COUNTIF(B4:K6,"2/3")+0*COUNTIF(B4:K6,"1/4")+0*COUNTIF(B4:K6,"0/5") -> 0 | N4: =5*COUNTIF(B4:K6,"5/0")+4*COUNTIF(B4:K6,"4/1")+3*COUNTIF(B4:K6,"3/2")+5*COUNTIF(B4:K6,"5/-")+2*COUNTIF(B4:K6,"2/3")+1*COUNTIF(B4:K6,"1/4")+0*COUNTIF(B4:K6,"0/5") -> 0 | O4: =0*COUNTIF(B4:K6,"5/0")+1*COUNTIF(B4:K6,"4/1")+2*COUNTIF(B4:K6,"3/2")+3*COUNTIF(B4:K6,"2/3")+4*COUNTIF(B4:K6,"1/4")+5*COUNTIF(B4:K6,"0/5")+5*COUNTIF(B4:K6,"-/5") -> 0 | P4: =RANK(L4,L$4:L$33) -> 1
P6: =IFERROR(L4/SUM(N4:O6),0) -> 0
A7: =C1 -> Tóth Zoltán | L7: =5*(COUNTIF(B7:K9,"5/0")+COUNTIF(B7:K9,"4/1")+COUNTIF(B7:K9,"3/2")+COUNTIF(B7:K9,"5/-"))+3*COUNTIF(B7:K9,"2/3")+2*COUNTIF(B7:K9,"1/4")+COUNTIF(B7:K9,"0/5")+0.01*M7+0.0001*(N7) -> 0 | M7: =1*COUNTIF(B7:K9,"5/0")+1*COUNTIF(B7:K9,"4/1")+1*COUNTIF(B7:K9,"3/2")+1*COUNTIF(B7:K9,"5/-")+0*COUNTIF(B7:K9,"2/3")+0*COUNTIF(B7:K9,"1/4")+0*COUNTIF(B7:K9,"0/5") -> 0 | N7: =5*COUNTIF(B7:K9,"5/0")+4*COUNTIF(B7:K9,"4/1")+3*COUNTIF(B7:K9,"3/2")+5*COUNTIF(B7:K9,"5/-")+2*COUNTIF(B7:K9,"2/3")+1*COUNTIF(B7:K9,"1/4")+0*COUNTIF(B7:K9,"0/5") -> 0 | O7: =0*COUNTIF(B7:K9,"5/0")+1*COUNTIF(B7:K9,"4/1")+2*COUNTIF(B7:K9,"3/2")+3*COUNTIF(B7:K9,"2/3")+4*COUNTIF(B7:K9,"1/4")+5*COUNTIF(B7:K9,"0/5")+5*COUNTIF(B7:K9,"-/5") -> 0 | P7: =RANK(L7,L$4:L$33) -> 1
P9: =IFERROR(L7/SUM(N7:O9),0) -> 0
A10: =D1 -> Polgár István | L10: =5*(COUNTIF(B10:K12,"5/0")+COUNTIF(B10:K12,"4/1")+COUNTIF(B10:K12,"3/2")+COUNTIF(B10:K12,"5/-"))+3*COUNTIF(B10:K12,"2/3")+2*COUNTIF(B10:K12,"1/4")+COUNTIF(B10:K12,"0/5")+0.01*M10+0.0001*(N10) -> 0 | M10: =1*COUNTIF(B10:K12,"5/0")+1*COUNTIF(B10:K12,"4/1")+1*COUNTIF(B10:K12,"3/2")+1*COUNTIF(B10:K12,"5/-")+0*COUNTIF(B10:K12,"2/3")+0*COUNTIF(B10:K12,"1/4")+0*COUNTIF(B10:K12,"0/5") -> 0 | N10: =5*COUNTIF(B10:K12,"5/0")+4*COUNTIF(B10:K12,"4/1")+3*COUNTIF(B10:K12,"3/2")+5*COUNTIF(B10:K12,"5/-")+2*COUNTIF(B10:K12,"2/3")+1*COUNTIF(B10:K12,"1/4")+0*COUNTIF(B10:K12,"0/5") -> 0 | O10: =0*COUNTIF(B10:K12,"5/0")+1*COUNTIF(B10:K12,"4/1")+2*COUNTIF(B10:K12,"3/2")+3*COUNTIF(B10:K12,"2/3")+4*COUNTIF(B10:K12,"1/4")+5*COUNTIF(B10:K12,"0/5")+5*COUNTIF(B10:K12,"-/5") -> 0 | P10: =RANK(L10,L$4:L$33) -> 1
P12: =IFERROR(L10/SUM(N10:O12),0) -> 0
A13: =E1 -> Weisz György | L13: =5*(COUNTIF(B13:K15,"5/0")+COUNTIF(B13:K15,"4/1")+COUNTIF(B13:K15,"3/2")+COUNTIF(B13:K15,"5/-"))+3*COUNTIF(B13:K15,"2/3")+2*COUNTIF(B13:K15,"1/4")+COUNTIF(B13:K15,"0/5")+0.01*M13+0.0001*(N13) -> 0 | M13: =1*COUNTIF(B13:K15,"5/0")+1*COUNTIF(B13:K15,"4/1")+1*COUNTIF(B13:K15,"3/2")+1*COUNTIF(B13:K15,"5/-")+0*COUNTIF(B13:K15,"2/3")+0*COUNTIF(B13:K15,"1/4")+0*COUNTIF(B13:K15,"0/5") -> 0 | N13: =5*COUNTIF(B13:K15,"5/0")+4*COUNTIF(B13:K15,"4/1")+3*COUNTIF(B13:K15,"3/2")+5*COUNTIF(B13:K15,"5/-")+2*COUNTIF(B13:K15,"2/3")+1*COUNTIF(B13:K15,"1/4")+0*COUNTIF(B13:K15,"0/5") -> 0 | O13: =0*COUNTIF(B13:K15,"5/0")+1*COUNTIF(B13:K15,"4/1")+2*COUNTIF(B13:K15,"3/2")+3*COUNTIF(B13:K15,"2/3")+4*COUNTIF(B13:K15,"1/4")+5*COUNTIF(B13:K15,"0/5")+5*COUNTIF(B13:K15,"-/5") -> 0 | P13: =RANK(L13,L$4:L$33) -> 1
P15: =IFERROR(L13/SUM(N13:O15),0) -> 0
A16: =F1 -> Nagy Ferenc | L16: =5*(COUNTIF(B16:K18,"5/0")+COUNTIF(B16:K18,"4/1")+COUNTIF(B16:K18,"3/2")+COUNTIF(B16:K18,"5/-"))+3*COUNTIF(B16:K18,"2/3")+2*COUNTIF(B16:K18,"1/4")+COUNTIF(B16:K18,"0/5")+0.01*M16+0.0001*(N16) -> 0 | M16: =1*COUNTIF(B16:K18,"5/0")+1*COUNTIF(B16:K18,"4/1")+1*COUNTIF(B16:K18,"3/2")+1*COUNTIF(B16:K18,"5/-")+0*COUNTIF(B16:K18,"2/3")+0*COUNTIF(B16:K18,"1/4")+0*COUNTIF(B16:K18,"0/5") -> 0 | N16: =5*COUNTIF(B16:K18,"5/0")+4*COUNTIF(B16:K18,"4/1")+3*COUNTIF(B16:K18,"3/2")+5*COUNTIF(B16:K18,"5/-")+2*COUNTIF(B16:K18,"2/3")+1*COUNTIF(B16:K18,"1/4")+0*COUNTIF(B16:K18,"0/5") -> 0 | O16: =0*COUNTIF(B16:K18,"5/0")+1*COUNTIF(B16:K18,"4/1")+2*COUNTIF(B16:K18,"3/2")+3*COUNTIF(B16:K18,"2/3")+4*COUNTIF(B16:K18,"1/4")+5*COUNTIF(B16:K18,"0/5")+5*COUNTIF(B16:K18,"-/5") -> 0 | P16: =RANK(L16,L$4:L$33) -> 1
P18: =IFERROR(L16/SUM(N16:O18),0) -> 0
A19: =G1 -> Dombay Miklós | L19: =5*(COUNTIF(B19:K21,"5/0")+COUNTIF(B19:K21,"4/1")+COUNTIF(B19:K21,"3/2")+COUNTIF(B19:K21,"5/-"))+3*COUNTIF(B19:K21,"2/3")+2*COUNTIF(B19:K21,"1/4")+COUNTIF(B19:K21,"0/5")+0.01*M19+0.0001*(N19) -> 0 | M19: =1*COUNTIF(B19:K21,"5/0")+1*COUNTIF(B19:K21,"4/1")+1*COUNTIF(B19:K21,"3/2")+1*COUNTIF(B19:K21,"5/-")+0*COUNTIF(B19:K21,"2/3")+0*COUNTIF(B19:K21,"1/4")+0*COUNTIF(B19:K21,"0/5") -> 0 | N19: =5*COUNTIF(B19:K21,"5/0")+4*COUNTIF(B19:K21,"4/1")+3*COUNTIF(B19:K21,"3/2")+5*COUNTIF(B19:K21,"5/-")+2*COUNTIF(B19:K21,"2/3")+1*COUNTIF(B19:K21,"1/4")+0*COUNTIF(B19:K21,"0/5") -> 0 | O19: =0*COUNTIF(B19:K21,"5/0")+1*COUNTIF(B19:K21,"4/1")+2*COUNTIF(B19:K21,"3/2")+3*COUNTIF(B19:K21,"2/3")+4*COUNTIF(B19:K21,"1/4")+5*COUNTIF(B19:K21,"0/5")+5*COUNTIF(B19:K21,"-/5") -> 0 | P19: =RANK(L19,L$4:L$33) -> 1
P21: =IFERROR(L19/SUM(N19:O21),0) -> 0
A22: =H1 -> Pék Róbert | L22: =5*(COUNTIF(B22:K24,"5/0")+COUNTIF(B22:K24,"4/1")+COUNTIF(B22:K24,"3/2")+COUNTIF(B22:K24,"5/-"))+3*COUNTIF(B22:K24,"2/3")+2*COUNTIF(B22:K24,"1/4")+COUNTIF(B22:K24,"0/5")+0.01*M22+0.0001*(N22) -> 0 | M22: =1*COUNTIF(B22:K24,"5/0")+1*COUNTIF(B22:K24,"4/1")+1*COUNTIF(B22:K24,"3/2")+1*COUNTIF(B22:K24,"5/-")+0*COUNTIF(B22:K24,"2/3")+0*COUNTIF(B22:K24,"1/4")+0*COUNTIF(B22:K24,"0/5") -> 0 | N22: =5*COUNTIF(B22:K24,"5/0")+4*COUNTIF(B22:K24,"4/1")+3*COUNTIF(B22:K24,"3/2")+5*COUNTIF(B22:K24,"5/-")+2*COUNTIF(B22:K24,"2/3")+1*COUNTIF(B22:K24,"1/4")+0*COUNTIF(B22:K24,"0/5") -> 0 | O22: =0*COUNTIF(B22:K24,"5/0")+1*COUNTIF(B22:K24,"4/1")+2*COUNTIF(B22:K24,"3/2")+3*COUNTIF(B22:K24,"2/3")+4*COUNTIF(B22:K24,"1/4")+5*COUNTIF(B22:K24,"0/5")+5*COUNTIF(B22:K24,"-/5") -> 0 | P22: =RANK(L22,L$4:L$33) -> 1
P24: =IFERROR(L22/SUM(N22:O24),0) -> 0
A25: =I1 -> Kovács Gábor | L25: =5*(COUNTIF(B25:K27,"5/0")+COUNTIF(B25:K27,"4/1")+COUNTIF(B25:K27,"3/2")+COUNTIF(B25:K27,"5/-"))+3*COUNTIF(B25:K27,"2/3")+2*COUNTIF(B25:K27,"1/4")+COUNTIF(B25:K27,"0/5")+0.01*M25+0.0001*(N25) -> 0 | M25: =1*COUNTIF(B25:K27,"5/0")+1*COUNTIF(B25:K27,"4/1")+1*COUNTIF(B25:K27,"3/2")+1*COUNTIF(B25:K27,"5/-")+0*COUNTIF(B25:K27,"2/3")+0*COUNTIF(B25:K27,"1/4")+0*COUNTIF(B25:K27,"0/5") -> 0 | N25: =5*COUNTIF(B25:K27,"5/0")+4*COUNTIF(B25:K27,"4/1")+3*COUNTIF(B25:K27,"3/2")+5*COUNTIF(B25:K27,"5/-")+2*COUNTIF(B25:K27,"2/3")+1*COUNTIF(B25:K27,"1/4")+0*COUNTIF(B25:K27,"0/5") -> 0 | O25: =0*COUNTIF(B25:K27,"5/0")+1*COUNTIF(B25:K27,"4/1")+2*COUNTIF(B25:K27,"3/2")+3*COUNTIF(B25:K27,"2/3")+4*COUNTIF(B25:K27,"1/4")+5*COUNTIF(B25:K27,"0/5")+5*COUNTIF(B25:K27,"-/5") -> 0 | P25: =RANK(L25,L$4:L$33) -> 1
P27: =IFERROR(L25/SUM(N25:O27),0) -> 0
A28: =J1 -> 0 | L28: =5*(COUNTIF(B28:K30,"5/0")+COUNTIF(B28:K30,"4/1")+COUNTIF(B28:K30,"3/2")+COUNTIF(B28:K30,"5/-"))+3*COUNTIF(B28:K30,"2/3")+2*COUNTIF(B28:K30,"1/4")+COUNTIF(B28:K30,"0/5")+0.01*M28+0.0001*(N28) -> 0 | M28: =1*COUNTIF(B28:K30,"5/0")+1*COUNTIF(B28:K30,"4/1")+1*COUNTIF(B28:K30,"3/2")+1*COUNTIF(B28:K30,"5/-")+0*COUNTIF(B28:K30,"2/3")+0*COUNTIF(B28:K30,"1/4")+0*COUNTIF(B28:K30,"0/5") -> 0 | N28: =5*COUNTIF(B28:K30,"5/0")+4*COUNTIF(B28:K30,"4/1")+3*COUNTIF(B28:K30,"3/2")+5*COUNTIF(B28:K30,"5/-")+2*COUNTIF(B28:K30,"2/3")+1*COUNTIF(B28:K30,"1/4")+0*COUNTIF(B28:K30,"0/5") -> 0 | O28: =0*COUNTIF(B28:K30,"5/0")+1*COUNTIF(B28:K30,"4/1")+2*COUNTIF(B28:K30,"3/2")+3*COUNTIF(B28:K30,"2/3")+4*COUNTIF(B28:K30,"1/4")+5*COUNTIF(B28:K30,"0/5")+5*COUNTIF(B28:K30,"-/5") -> 0 | P28: =RANK(L28,L$4:L$33) -> 1
P30: =IFERROR(L28/SUM(N28:O30),0) -> 0
A31: =K1 -> 0 | L31: =5*(COUNTIF(B31:K33,"5/0")+COUNTIF(B31:K33,"4/1")+COUNTIF(B31:K33,"3/2")+COUNTIF(B31:K33,"5/-"))+3*COUNTIF(B31:K33,"2/3")+2*COUNTIF(B31:K33,"1/4")+COUNTIF(B31:K33,"0/5")+0.01*M31+0.0001*(N31) -> 0 | M31: =1*COUNTIF(B31:K33,"5/0")+1*COUNTIF(B31:K33,"4/1")+1*COUNTIF(B31:K33,"3/2")+1*COUNTIF(B31:K33,"5/-")+0*COUNTIF(B31:K33,"2/3")+0*COUNTIF(B31:K33,"1/4")+0*COUNTIF(B31:K33,"0/5") -> 0 | N31: =5*COUNTIF(B31:K33,"5/0")+4*COUNTIF(B31:K33,"4/1")+3*COUNTIF(B31:K33,"3/2")+5*COUNTIF(B31:K33,"5/-")+2*COUNTIF(B31:K33,"2/3")+1*COUNTIF(B31:K33,"1/4")+0*COUNTIF(B31:K33,"0/5") -> 0 | O31: =0*COUNTIF(B31:K33,"5/0")+1*COUNTIF(B31:K33,"4/1")+2*COUNTIF(B31:K33,"3/2")+3*COUNTIF(B31:K33,"2/3")+4*COUNTIF(B31:K33,"1/4")+5*COUNTIF(B31:K33,"0/5")+5*COUNTIF(B31:K33,"-/5") -> 0 | P31: =RANK(L31,L$4:L$33) -> 1
P33: =IFERROR(L31/SUM(N31:O33),0) -> 0

Sheet B liga
B1: =VLOOKUP(CONCATENATE(LEFT($A$2,1),COLUMN()-1),nevezettek,3,FALSE) -> Sákovics Péter | C1: =VLOOKUP(CONCATENATE(LEFT($A$2,1),COLUMN()-1),nevezettek,3,FALSE) -> Tóth István | D1: =VLOOKUP(CONCATENATE(LEFT($A$2,1),COLUMN()-1),nevezettek,3,FALSE) -> Kulcsár Sándor | E1: =VLOOKUP(CONCATENATE(LEFT($A$2,1),COLUMN()-1),nevezettek,3,FALSE) -> Bikali Balázs | F1: =VLOOKUP(CONCATENATE(LEFT($A$2,1),COLUMN()-1),nevezettek,3,FALSE) -> Markó Zoltán | G1: =VLOOKUP(CONCATENATE(LEFT($A$2,1),COLUMN()-1),nevezettek,3,FALSE) -> Czupor András | H1: =VLOOKUP(CONCATENATE(LEFT($A$2,1),COLUMN()-1),nevezettek,3,FALSE) -> Varga Lorena | I1: =VLOOKUP(CONCATENATE(LEFT($A$2,1),COLUMN()-1),nevezettek,3,FALSE) -> Kovács László | ... K1: =VLOOKUP(CONCATENATE(LEFT($A$2,1),COLUMN()-1),nevezettek,3,FALSE) -> 0 | L1: összpont-szám | M1: Győze-lem | N1: Nyert szett | O1: Vesztett szett | P1: helyezés (hatékonyság)
A2: =RIGHT(CELL("filename",A1),6) -> B liga
A3: =COUNTIF(Ligabeosztas!D:D,LEFT(A2,1)) -> 10
A4: =B1 -> Sákovics Péter | L4: =5*(COUNTIF(B4:K6,"5/0")+COUNTIF(B4:K6,"4/1")+COUNTIF(B4:K6,"3/2")+COUNTIF(B4:K6,"5/-"))+3*COUNTIF(B4:K6,"2/3")+2*COUNTIF(B4:K6,"1/4")+COUNTIF(B4:K6,"0/5")+0.01*M4+0.0001*(N4) -> 0 | M4: =1*COUNTIF(B4:K6,"5/0")+1*COUNTIF(B4:K6,"4/1")+1*COUNTIF(B4:K6,"3/2")+1*COUNTIF(B4:K6,"5/-")+0*COUNTIF(B4:K6,"2/3")+0*COUNTIF(B4:K6,"1/4")+0*COUNTIF(B4:K6,"0/5") -> 0 | N4: =5*COUNTIF(B4:K6,"5/0")+4*COUNTIF(B4:K6,"4/1")+3*COUNTIF(B4:K6,"3/2")+5*COUNTIF(B4:K6,"5/-")+2*COUNTIF(B4:K6,"2/3")+1*COUNTIF(B4:K6,"1/4")+0*COUNTIF(B4:K6,"0/5") -> 0 | O4: =0*COUNTIF(B4:K6,"5/0")+1*COUNTIF(B4:K6,"4/1")+2*COUNTIF(B4:K6,"3/2")+3*COUNTIF(B4:K6,"2/3")+4*COUNTIF(B4:K6,"1/4")+5*COUNTIF(B4:K6,"0/5")+5*COUNTIF(B4:K6,"-/5") -> 0 | P4: =RANK(L4,L$4:L$33) -> 1
P6: =IFERROR(L4/SUM(N4:O6),0) -> 0
A7: =C1 -> Tóth István | L7: =5*(COUNTIF(B7:K9,"5/0")+COUNTIF(B7:K9,"4/1")+COUNTIF(B7:K9,"3/2")+COUNTIF(B7:K9,"5/-"))+3*COUNTIF(B7:K9,"2/3")+2*COUNTIF(B7:K9,"1/4")+COUNTIF(B7:K9,"0/5")+0.01*M7+0.0001*(N7) -> 0 | M7: =1*COUNTIF(B7:K9,"5/0")+1*COUNTIF(B7:K9,"4/1")+1*COUNTIF(B7:K9,"3/2")+1*COUNTIF(B7:K9,"5/-")+0*COUNTIF(B7:K9,"2/3")+0*COUNTIF(B7:K9,"1/4")+0*COUNTIF(B7:K9,"0/5") -> 0 | N7: =5*COUNTIF(B7:K9,"5/0")+4*COUNTIF(B7:K9,"4/1")+3*COUNTIF(B7:K9,"3/2")+5*COUNTIF(B7:K9,"5/-")+2*COUNTIF(B7:K9,"2/3")+1*COUNTIF(B7:K9,"1/4")+0*COUNTIF(B7:K9,"0/5") -> 0 | O7: =0*COUNTIF(B7:K9,"5/0")+1*COUNTIF(B7:K9,"4/1")+2*COUNTIF(B7:K9,"3/2")+3*COUNTIF(B7:K9,"2/3")+4*COUNTIF(B7:K9,"1/4")+5*COUNTIF(B7:K9,"0/5")+5*COUNTIF(B7:K9,"-/5") -> 0 | P7: =RANK(L7,L$4:L$33) -> 1
P9: =IFERROR(L7/SUM(N7:O9),0) -> 0
A10: =D1 -> Kulcsár Sándor | L10: =5*(COUNTIF(B10:K12,"5/0")+COUNTIF(B10:K12,"4/1")+COUNTIF(B10:K12,"3/2")+COUNTIF(B10:K12,"5/-"))+3*COUNTIF(B10:K12,"2/3")+2*COUNTIF(B10:K12,"1/4")+COUNTIF(B10:K12,"0/5")+0.01*M10+0.0001*(N10) -> 0 | M10: =1*COUNTIF(B10:K12,"5/0")+1*COUNTIF(B10:K12,"4/1")+1*COUNTIF(B10:K12,"3/2")+1*COUNTIF(B10:K12,"5/-")+0*COUNTIF(B10:K12,"2/3")+0*COUNTIF(B10:K12,"1/4")+0*COUNTIF(B10:K12,"0/5") -> 0 | N10: =5*COUNTIF(B10:K12,"5/0")+4*COUNTIF(B10:K12,"4/1")+3*COUNTIF(B10:K12,"3/2")+5*COUNTIF(B10:K12,"5/-")+2*COUNTIF(B10:K12,"2/3")+1*COUNTIF(B10:K12,"1/4")+0*COUNTIF(B10:K12,"0/5") -> 0 | O10: =0*COUNTIF(B10:K12,"5/0")+1*COUNTIF(B10:K12,"4/1")+2*COUNTIF(B10:K12,"3/2")+3*COUNTIF(B10:K12,"2/3")+4*COUNTIF(B10:K12,"1/4")+5*COUNTIF(B10:K12,"0/5")+5*COUNTIF(B10:K12,"-/5") -> 0 | P10: =RANK(L10,L$4:L$33) -> 1
P12: =IFERROR(L10/SUM(N10:O12),0) -> 0
A13: =E1 -> Bikali Balázs | L13: =5*(COUNTIF(B13:K15,"5/0")+COUNTIF(B13:K15,"4/1")+COUNTIF(B13:K15,"3/2")+COUNTIF(B13:K15,"5/-"))+3*COUNTIF(B13:K15,"2/3")+2*COUNTIF(B13:K15,"1/4")+COUNTIF(B13:K15,"0/5")+0.01*M13+0.0001*(N13) -> 0 | M13: =1*COUNTIF(B13:K15,"5/0")+1*COUNTIF(B13:K15,"4/1")+1*COUNTIF(B13:K15,"3/2")+1*COUNTIF(B13:K15,"5/-")+0*COUNTIF(B13:K15,"2/3")+0*COUNTIF(B13:K15,"1/4")+0*COUNTIF(B13:K15,"0/5") -> 0 | N13: =5*COUNTIF(B13:K15,"5/0")+4*COUNTIF(B13:K15,"4/1")+3*COUNTIF(B13:K15,"3/2")+5*COUNTIF(B13:K15,"5/-")+2*COUNTIF(B13:K15,"2/3")+1*COUNTIF(B13:K15,"1/4")+0*COUNTIF(B13:K15,"0/5") -> 0 | O13: =0*COUNTIF(B13:K15,"5/0")+1*COUNTIF(B13:K15,"4/1")+2*COUNTIF(B13:K15,"3/2")+3*COUNTIF(B13:K15,"2/3")+4*COUNTIF(B13:K15,"1/4")+5*COUNTIF(B13:K15,"0/5")+5*COUNTIF(B13:K15,"-/5") -> 0 | P13: =RANK(L13,L$4:L$33) -> 1
P15: =IFERROR(L13/SUM(N13:O15),0) -> 0
A16: =F1 -> Markó Zoltán | L16: =5*(COUNTIF(B16:K18,"5/0")+COUNTIF(B16:K18,"4/1")+COUNTIF(B16:K18,"3/2")+COUNTIF(B16:K18,"5/-"))+3*COUNTIF(B16:K18,"2/3")+2*COUNTIF(B16:K18,"1/4")+COUNTIF(B16:K18,"0/5")+0.01*M16+0.0001*(N16) -> 0 | M16: =1*COUNTIF(B16:K18,"5/0")+1*COUNTIF(B16:K18,"4/1")+1*COUNTIF(B16:K18,"3/2")+1*COUNTIF(B16:K18,"5/-")+0*COUNTIF(B16:K18,"2/3")+0*COUNTIF(B16:K18,"1/4")+0*COUNTIF(B16:K18,"0/5") -> 0 | N16: =5*COUNTIF(B16:K18,"5/0")+4*COUNTIF(B16:K18,"4/1")+3*COUNTIF(B16:K18,"3/2")+5*COUNTIF(B16:K18,"5/-")+2*COUNTIF(B16:K18,"2/3")+1*COUNTIF(B16:K18,"1/4")+0*COUNTIF(B16:K18,"0/5") -> 0 | O16: =0*COUNTIF(B16:K18,"5/0")+1*COUNTIF(B16:K18,"4/1")+2*COUNTIF(B16:K18,"3/2")+3*COUNTIF(B16:K18,"2/3")+4*COUNTIF(B16:K18,"1/4")+5*COUNTIF(B16:K18,"0/5")+5*COUNTIF(B16:K18,"-/5") -> 0 | P16: =RANK(L16,L$4:L$33) -> 1
P18: =IFERROR(L16/SUM(N16:O18),0) -> 0
A19: =G1 -> Czupor András | L19: =5*(COUNTIF(B19:K21,"5/0")+COUNTIF(B19:K21,"4/1")+COUNTIF(B19:K21,"3/2")+COUNTIF(B19:K21,"5/-"))+3*COUNTIF(B19:K21,"2/3")+2*COUNTIF(B19:K21,"1/4")+COUNTIF(B19:K21,"0/5")+0.01*M19+0.0001*(N19) -> 0 | M19: =1*COUNTIF(B19:K21,"5/0")+1*COUNTIF(B19:K21,"4/1")+1*COUNTIF(B19:K21,"3/2")+1*COUNTIF(B19:K21,"5/-")+0*COUNTIF(B19:K21,"2/3")+0*COUNTIF(B19:K21,"1/4")+0*COUNTIF(B19:K21,"0/5") -> 0 | N19: =5*COUNTIF(B19:K21,"5/0")+4*COUNTIF(B19:K21,"4/1")+3*COUNTIF(B19:K21,"3/2")+5*COUNTIF(B19:K21,"5/-")+2*COUNTIF(B19:K21,"2/3")+1*COUNTIF(B19:K21,"1/4")+0*COUNTIF(B19:K21,"0/5") -> 0 | O19: =0*COUNTIF(B19:K21,"5/0")+1*COUNTIF(B19:K21,"4/1")+2*COUNTIF(B19:K21,"3/2")+3*COUNTIF(B19:K21,"2/3")+4*COUNTIF(B19:K21,"1/4")+5*COUNTIF(B19:K21,"0/5")+5*COUNTIF(B19:K21,"-/5") -> 0 | P19: =RANK(L19,L$4:L$33) -> 1
P21: =IFERROR(L19/SUM(N19:O21),0) -> 0
A22: =H1 -> Varga Lorena | L22: =5*(COUNTIF(B22:K24,"5/0")+COUNTIF(B22:K24,"4/1")+COUNTIF(B22:K24,"3/2")+COUNTIF(B22:K24,"5/-"))+3*COUNTIF(B22:K24,"2/3")+2*COUNTIF(B22:K24,"1/4")+COUNTIF(B22:K24,"0/5")+0.01*M22+0.0001*(N22) -> 0 | M22: =1*COUNTIF(B22:K24,"5/0")+1*COUNTIF(B22:K24,"4/1")+1*COUNTIF(B22:K24,"3/2")+1*COUNTIF(B22:K24,"5/-")+0*COUNTIF(B22:K24,"2/3")+0*COUNTIF(B22:K24,"1/4")+0*COUNTIF(B22:K24,"0/5") -> 0 | N22: =5*COUNTIF(B22:K24,"5/0")+4*COUNTIF(B22:K24,"4/1")+3*COUNTIF(B22:K24,"3/2")+5*COUNTIF(B22:K24,"5/-")+2*COUNTIF(B22:K24,"2/3")+1*COUNTIF(B22:K24,"1/4")+0*COUNTIF(B22:K24,"0/5") -> 0 | O22: =0*COUNTIF(B22:K24,"5/0")+1*COUNTIF(B22:K24,"4/1")+2*COUNTIF(B22:K24,"3/2")+3*COUNTIF(B22:K24,"2/3")+4*COUNTIF(B22:K24,"1/4")+5*COUNTIF(B22:K24,"0/5")+5*COUNTIF(B22:K24,"-/5") -> 0 | P22: =RANK(L22,L$4:L$33) -> 1
P24: =IFERROR(L22/SUM(N22:O24),0) -> 0
A25: =I1 -> Kovács László | L25: =5*(COUNTIF(B25:K27,"5/0")+COUNTIF(B25:K27,"4/1")+COUNTIF(B25:K27,"3/2")+COUNTIF(B25:K27,"5/-"))+3*COUNTIF(B25:K27,"2/3")+2*COUNTIF(B25:K27,"1/4")+COUNTIF(B25:K27,"0/5")+0.01*M25+0.0001*(N25) -> 0 | M25: =1*COUNTIF(B25:K27,"5/0")+1*COUNTIF(B25:K27,"4/1")+1*COUNTIF(B25:K27,"3/2")+1*COUNTIF(B25:K27,"5/-")+0*COUNTIF(B25:K27,"2/3")+0*COUNTIF(B25:K27,"1/4")+0*COUNTIF(B25:K27,"0/5") -> 0 | N25: =5*COUNTIF(B25:K27,"5/0")+4*COUNTIF(B25:K27,"4/1")+3*COUNTIF(B25:K27,"3/2")+5*COUNTIF(B25:K27,"5/-")+2*COUNTIF(B25:K27,"2/3")+1*COUNTIF(B25:K27,"1/4")+0*COUNTIF(B25:K27,"0/5") -> 0 | O25: =0*COUNTIF(B25:K27,"5/0")+1*COUNTIF(B25:K27,"4/1")+2*COUNTIF(B25:K27,"3/2")+3*COUNTIF(B25:K27,"2/3")+4*COUNTIF(B25:K27,"1/4")+5*COUNTIF(B25:K27,"0/5")+5*COUNTIF(B25:K27,"-/5") -> 0 | P25: =RANK(L25,L$4:L$33) -> 1
P27: =IFERROR(L25/SUM(N25:O27),0) -> 0
A28: =J1 -> 0 | L28: =5*(COUNTIF(B28:K30,"5/0")+COUNTIF(B28:K30,"4/1")+COUNTIF(B28:K30,"3/2")+COUNTIF(B28:K30,"5/-"))+3*COUNTIF(B28:K30,"2/3")+2*COUNTIF(B28:K30,"1/4")+COUNTIF(B28:K30,"0/5")+0.01*M28+0.0001*(N28) -> 0 | M28: =1*COUNTIF(B28:K30,"5/0")+1*COUNTIF(B28:K30,"4/1")+1*COUNTIF(B28:K30,"3/2")+1*COUNTIF(B28:K30,"5/-")+0*COUNTIF(B28:K30,"2/3")+0*COUNTIF(B28:K30,"1/4")+0*COUNTIF(B28:K30,"0/5") -> 0 | N28: =5*COUNTIF(B28:K30,"5/0")+4*COUNTIF(B28:K30,"4/1")+3*COUNTIF(B28:K30,"3/2")+5*COUNTIF(B28:K30,"5/-")+2*COUNTIF(B28:K30,"2/3")+1*COUNTIF(B28:K30,"1/4")+0*COUNTIF(B28:K30,"0/5") -> 0 | O28: =0*COUNTIF(B28:K30,"5/0")+1*COUNTIF(B28:K30,"4/1")+2*COUNTIF(B28:K30,"3/2")+3*COUNTIF(B28:K30,"2/3")+4*COUNTIF(B28:K30,"1/4")+5*COUNTIF(B28:K30,"0/5")+5*COUNTIF(B28:K30,"-/5") -> 0 | P28: =RANK(L28,L$4:L$33) -> 1
P30: =IFERROR(L28/SUM(N28:O30),0) -> 0
A31: =K1 -> 0 | L31: =5*(COUNTIF(B31:K33,"5/0")+COUNTIF(B31:K33,"4/1")+COUNTIF(B31:K33,"3/2")+COUNTIF(B31:K33,"5/-"))+3*COUNTIF(B31:K33,"2/3")+2*COUNTIF(B31:K33,"1/4")+COUNTIF(B31:K33,"0/5")+0.01*M31+0.0001*(N31) -> 0 | M31: =1*COUNTIF(B31:K33,"5/0")+1*COUNTIF(B31:K33,"4/1")+1*COUNTIF(B31:K33,"3/2")+1*COUNTIF(B31:K33,"5/-")+0*COUNTIF(B31:K33,"2/3")+0*COUNTIF(B31:K33,"1/4")+0*COUNTIF(B31:K33,"0/5") -> 0 | N31: =5*COUNTIF(B31:K33,"5/0")+4*COUNTIF(B31:K33,"4/1")+3*COUNTIF(B31:K33,"3/2")+5*COUNTIF(B31:K33,"5/-")+2*COUNTIF(B31:K33,"2/3")+1*COUNTIF(B31:K33,"1/4")+0*COUNTIF(B31:K33,"0/5") -> 0 | O31: =0*COUNTIF(B31:K33,"5/0")+1*COUNTIF(B31:K33,"4/1")+2*COUNTIF(B31:K33,"3/2")+3*COUNTIF(B31:K33,"2/3")+4*COUNTIF(B31:K33,"1/4")+5*COUNTIF(B31:K33,"0/5")+5*COUNTIF(B31:K33,"-/5") -> 0 | P31: =RANK(L31,L$4:L$33) -> 1
P33: =IFERROR(L31/SUM(N31:O33),0) -> 0

Sheet C liga
B1: =VLOOKUP(CONCATENATE(LEFT($A$2,1),COLUMN()-1),nevezettek,3,FALSE) -> Székely Árpád | C1: =VLOOKUP(CONCATENATE(LEFT($A$2,1),COLUMN()-1),nevezettek,3,FALSE) -> Tóth Bálint | D1: =VLOOKUP(CONCATENATE(LEFT($A$2,1),COLUMN()-1),nevezettek,3,FALSE) -> Börzsönyi Balázs | E1: =VLOOKUP(CONCATENATE(LEFT($A$2,1),COLUMN()-1),nevezettek,3,FALSE) -> Kmet Alex | F1: =VLOOKUP(CONCATENATE(LEFT($A$2,1),COLUMN()-1),nevezettek,3,FALSE) -> Bartus Péter | G1: =VLOOKUP(CONCATENATE(LEFT($A$2,1),COLUMN()-1),nevezettek,3,FALSE) -> Fekete Tamás | H1: =VLOOKUP(CONCATENATE(LEFT($A$2,1),COLUMN()-1),nevezettek,3,FALSE) -> Varga Tamás | I1: =VLOOKUP(CONCATENATE(LEFT($A$2,1),COLUMN()-1),nevezettek,3,FALSE) -> Hatos Balázs | ... L1: =VLOOKUP(CONCATENATE(LEFT($A$2,1),COLUMN()-1),nevezettek,3,FALSE) -> 0 | M1: összpont-szám | N1: Győze-lem | O1: Nyert szett | P1: Vesztett szett | Q1: helyezés (hatékonyság)
A2: =RIGHT(CELL("filename",A1),6) -> C liga
A3: =COUNTIF(Ligabeosztas!D:D,LEFT(A2,1)) -> 11
A4: =B1 -> Székely Árpád | M4: =5*(COUNTIF(B4:L6,"5/0")+COUNTIF(B4:L6,"4/1")+COUNTIF(B4:L6,"3/2")+COUNTIF(B4:L6,"5/-"))+3*COUNTIF(B4:L6,"2/3")+2*COUNTIF(B4:L6,"1/4")+COUNTIF(B4:L6,"0/5")+0.01*N4+0.0001*(O4) -> 0 | N4: =1*COUNTIF(B4:L6,"5/0")+1*COUNTIF(B4:L6,"4/1")+1*COUNTIF(B4:L6,"3/2")+1*COUNTIF(B4:L6,"5/-")+0*COUNTIF(B4:L6,"2/3")+0*COUNTIF(B4:L6,"1/4")+0*COUNTIF(B4:L6,"0/5") -> 0 | O4: =5*COUNTIF(B4:L6,"5/0")+4*COUNTIF(B4:L6,"4/1")+3*COUNTIF(B4:L6,"3/2")+5*COUNTIF(B4:L6,"5/-")+2*COUNTIF(B4:L6,"2/3")+1*COUNTIF(B4:L6,"1/4")+0*COUNTIF(B4:L6,"0/5") -> 0 | P4: =0*COUNTIF(B4:L6,"5/0")+1*COUNTIF(B4:L6,"4/1")+2*COUNTIF(B4:L6,"3/2")+3*COUNTIF(B4:L6,"2/3")+4*COUNTIF(B4:L6,"1/4")+5*COUNTIF(B4:L6,"0/5")+5*COUNTIF(B4:L6,"-/5") -> 0 | Q4: =RANK(M4,M$4:M$36) -> 1
Q6: =IFERROR(M4/SUM(O4:P6),0) -> 0
A7: =C1 -> Tóth Bálint | M7: =5*(COUNTIF(B7:L9,"5/0")+COUNTIF(B7:L9,"4/1")+COUNTIF(B7:L9,"3/2")+COUNTIF(B7:L9,"5/-"))+3*COUNTIF(B7:L9,"2/3")+2*COUNTIF(B7:L9,"1/4")+COUNTIF(B7:L9,"0/5")+0.01*N7+0.0001*(O7) -> 0 | N7: =1*COUNTIF(B7:L9,"5/0")+1*COUNTIF(B7:L9,"4/1")+1*COUNTIF(B7:L9,"3/2")+1*COUNTIF(B7:L9,"5/-")+0*COUNTIF(B7:L9,"2/3")+0*COUNTIF(B7:L9,"1/4")+0*COUNTIF(B7:L9,"0/5") -> 0 | O7: =5*COUNTIF(B7:L9,"5/0")+4*COUNTIF(B7:L9,"4/1")+3*COUNTIF(B7:L9,"3/2")+5*COUNTIF(B7:L9,"5/-")+2*COUNTIF(B7:L9,"2/3")+1*COUNTIF(B7:L9,"1/4")+0*COUNTIF(B7:L9,"0/5") -> 0 | P7: =0*COUNTIF(B7:L9,"5/0")+1*COUNTIF(B7:L9,"4/1")+2*COUNTIF(B7:L9,"3/2")+3*COUNTIF(B7:L9,"2/3")+4*COUNTIF(B7:L9,"1/4")+5*COUNTIF(B7:L9,"0/5")+5*COUNTIF(B7:L9,"-/5") -> 0 | Q7: =RANK(M7,M$4:M$36) -> 1
Q9: =IFERROR(M7/SUM(O7:P9),0) -> 0
A10: =D1 -> Börzsönyi Balázs | M10: =5*(COUNTIF(B10:L12,"5/0")+COUNTIF(B10:L12,"4/1")+COUNTIF(B10:L12,"3/2")+COUNTIF(B10:L12,"5/-"))+3*COUNTIF(B10:L12,"2/3")+2*COUNTIF(B10:L12,"1/4")+COUNTIF(B10:L12,"0/5")+0.01*N10+0.0001*(O10) -> 0 | N10: =1*COUNTIF(B10:L12,"5/0")+1*COUNTIF(B10:L12,"4/1")+1*COUNTIF(B10:L12,"3/2")+1*COUNTIF(B10:L12,"5/-")+0*COUNTIF(B10:L12,"2/3")+0*COUNTIF(B10:L12,"1/4")+0*COUNTIF(B10:L12,"0/5") -> 0 | O10: =5*COUNTIF(B10:L12,"5/0")+4*COUNTIF(B10:L12,"4/1")+3*COUNTIF(B10:L12,"3/2")+5*COUNTIF(B10:L12,"5/-")+2*COUNTIF(B10:L12,"2/3")+1*COUNTIF(B10:L12,"1/4")+0*COUNTIF(B10:L12,"0/5") -> 0 | P10: =0*COUNTIF(B10:L12,"5/0")+1*COUNTIF(B10:L12,"4/1")+2*COUNTIF(B10:L12,"3/2")+3*COUNTIF(B10:L12,"2/3")+4*COUNTIF(B10:L12,"1/4")+5*COUNTIF(B10:L12,"0/5")+5*COUNTIF(B10:L12,"-/5") -> 0 | Q10: =RANK(M10,M$4:M$36) -> 1
Q12: =IFERROR(M10/SUM(O10:P12),0) -> 0
A13: =E1 -> Kmet Alex | M13: =5*(COUNTIF(B13:L15,"5/0")+COUNTIF(B13:L15,"4/1")+COUNTIF(B13:L15,"3/2")+COUNTIF(B13:L15,"5/-"))+3*COUNTIF(B13:L15,"2/3")+2*COUNTIF(B13:L15,"1/4")+COUNTIF(B13:L15,"0/5")+0.01*N13+0.0001*(O13) -> 0 | N13: =1*COUNTIF(B13:L15,"5/0")+1*COUNTIF(B13:L15,"4/1")+1*COUNTIF(B13:L15,"3/2")+1*COUNTIF(B13:L15,"5/-")+0*COUNTIF(B13:L15,"2/3")+0*COUNTIF(B13:L15,"1/4")+0*COUNTIF(B13:L15,"0/5") -> 0 | O13: =5*COUNTIF(B13:L15,"5/0")+4*COUNTIF(B13:L15,"4/1")+3*COUNTIF(B13:L15,"3/2")+5*COUNTIF(B13:L15,"5/-")+2*COUNTIF(B13:L15,"2/3")+1*COUNTIF(B13:L15,"1/4")+0*COUNTIF(B13:L15,"0/5") -> 0 | P13: =0*COUNTIF(B13:L15,"5/0")+1*COUNTIF(B13:L15,"4/1")+2*COUNTIF(B13:L15,"3/2")+3*COUNTIF(B13:L15,"2/3")+4*COUNTIF(B13:L15,"1/4")+5*COUNTIF(B13:L15,"0/5")+5*COUNTIF(B13:L15,"-/5") -> 0 | Q13: =RANK(M13,M$4:M$36) -> 1
Q15: =IFERROR(M13/SUM(O13:P15),0) -> 0
A16: =F1 -> Bartus Péter | M16: =5*(COUNTIF(B16:L18,"5/0")+COUNTIF(B16:L18,"4/1")+COUNTIF(B16:L18,"3/2")+COUNTIF(B16:L18,"5/-"))+3*COUNTIF(B16:L18,"2/3")+2*COUNTIF(B16:L18,"1/4")+COUNTIF(B16:L18,"0/5")+0.01*N16+0.0001*(O16) -> 0 | N16: =1*COUNTIF(B16:L18,"5/0")+1*COUNTIF(B16:L18,"4/1")+1*COUNTIF(B16:L18,"3/2")+1*COUNTIF(B16:L18,"5/-")+0*COUNTIF(B16:L18,"2/3")+0*COUNTIF(B16:L18,"1/4")+0*COUNTIF(B16:L18,"0/5") -> 0 | O16: =5*COUNTIF(B16:L18,"5/0")+4*COUNTIF(B16:L18,"4/1")+3*COUNTIF(B16:L18,"3/2")+5*COUNTIF(B16:L18,"5/-")+2*COUNTIF(B16:L18,"2/3")+1*COUNTIF(B16:L18,"1/4")+0*COUNTIF(B16:L18,"0/5") -> 0 | P16: =0*COUNTIF(B16:L18,"5/0")+1*COUNTIF(B16:L18,"4/1")+2*COUNTIF(B16:L18,"3/2")+3*COUNTIF(B16:L18,"2/3")+4*COUNTIF(B16:L18,"1/4")+5*COUNTIF(B16:L18,"0/5")+5*COUNTIF(B16:L18,"-/5") -> 0 | Q16: =RANK(M16,M$4:M$36) -> 1
Q18: =IFERROR(M16/SUM(O16:P18),0) -> 0
A19: =G1 -> Fekete Tamás | M19: =5*(COUNTIF(B19:L21,"5/0")+COUNTIF(B19:L21,"4/1")+COUNTIF(B19:L21,"3/2")+COUNTIF(B19:L21,"5/-"))+3*COUNTIF(B19:L21,"2/3")+2*COUNTIF(B19:L21,"1/4")+COUNTIF(B19:L21,"0/5")+0.01*N19+0.0001*(O19) -> 0 | N19: =1*COUNTIF(B19:L21,"5/0")+1*COUNTIF(B19:L21,"4/1")+1*COUNTIF(B19:L21,"3/2")+1*COUNTIF(B19:L21,"5/-")+0*COUNTIF(B19:L21,"2/3")+0*COUNTIF(B19:L21,"1/4")+0*COUNTIF(B19:L21,"0/5") -> 0 | O19: =5*COUNTIF(B19:L21,"5/0")+4*COUNTIF(B19:L21,"4/1")+3*COUNTIF(B19:L21,"3/2")+5*COUNTIF(B19:L21,"5/-")+2*COUNTIF(B19:L21,"2/3")+1*COUNTIF(B19:L21,"1/4")+0*COUNTIF(B19:L21,"0/5") -> 0 | P19: =0*COUNTIF(B19:L21,"5/0")+1*COUNTIF(B19:L21,"4/1")+2*COUNTIF(B19:L21,"3/2")+3*COUNTIF(B19:L21,"2/3")+4*COUNTIF(B19:L21,"1/4")+5*COUNTIF(B19:L21,"0/5")+5*COUNTIF(B19:L21,"-/5") -> 0 | Q19: =RANK(M19,M$4:M$36) -> 1
Q21: =IFERROR(M19/SUM(O19:P21),0) -> 0
A22: =H1 -> Varga Tamás | M22: =5*(COUNTIF(B22:L24,"5/0")+COUNTIF(B22:L24,"4/1")+COUNTIF(B22:L24,"3/2")+COUNTIF(B22:L24,"5/-"))+3*COUNTIF(B22:L24,"2/3")+2*COUNTIF(B22:L24,"1/4")+COUNTIF(B22:L24,"0/5")+0.01*N22+0.0001*(O22) -> 0 | N22: =1*COUNTIF(B22:L24,"5/0")+1*COUNTIF(B22:L24,"4/1")+1*COUNTIF(B22:L24,"3/2")+1*COUNTIF(B22:L24,"5/-")+0*COUNTIF(B22:L24,"2/3")+0*COUNTIF(B22:L24,"1/4")+0*COUNTIF(B22:L24,"0/5") -> 0 | O22: =5*COUNTIF(B22:L24,"5/0")+4*COUNTIF(B22:L24,"4/1")+3*COUNTIF(B22:L24,"3/2")+5*COUNTIF(B22:L24,"5/-")+2*COUNTIF(B22:L24,"2/3")+1*COUNTIF(B22:L24,"1/4")+0*COUNTIF(B22:L24,"0/5") -> 0 | P22: =0*COUNTIF(B22:L24,"5/0")+1*COUNTIF(B22:L24,"4/1")+2*COUNTIF(B22:L24,"3/2")+3*COUNTIF(B22:L24,"2/3")+4*COUNTIF(B22:L24,"1/4")+5*COUNTIF(B22:L24,"0/5")+5*COUNTIF(B22:L24,"-/5") -> 0 | Q22: =RANK(M22,M$4:M$36) -> 1
Q24: =IFERROR(M22/SUM(O22:P24),0) -> 0
A25: =I1 -> Hatos Balázs | M25: =5*(COUNTIF(B25:L27,"5/0")+COUNTIF(B25:L27,"4/1")+COUNTIF(B25:L27,"3/2")+COUNTIF(B25:L27,"5/-"))+3*COUNTIF(B25:L27,"2/3")+2*COUNTIF(B25:L27,"1/4")+COUNTIF(B25:L27,"0/5")+0.01*N25+0.0001*(O25) -> 0 | N25: =1*COUNTIF(B25:L27,"5/0")+1*COUNTIF(B25:L27,"4/1")+1*COUNTIF(B25:L27,"3/2")+1*COUNTIF(B25:L27,"5/-")+0*COUNTIF(B25:L27,"2/3")+0*COUNTIF(B25:L27,"1/4")+0*COUNTIF(B25:L27,"0/5") -> 0 | O25: =5*COUNTIF(B25:L27,"5/0")+4*COUNTIF(B25:L27,"4/1")+3*COUNTIF(B25:L27,"3/2")+5*COUNTIF(B25:L27,"5/-")+2*COUNTIF(B25:L27,"2/3")+1*COUNTIF(B25:L27,"1/4")+0*COUNTIF(B25:L27,"0/5") -> 0 | P25: =0*COUNTIF(B25:L27,"5/0")+1*COUNTIF(B25:L27,"4/1")+2*COUNTIF(B25:L27,"3/2")+3*COUNTIF(B25:L27,"2/3")+4*COUNTIF(B25:L27,"1/4")+5*COUNTIF(B25:L27,"0/5")+5*COUNTIF(B25:L27,"-/5") -> 0 | Q25: =RANK(M25,M$4:M$36) -> 1
Q27: =IFERROR(M25/SUM(O25:P27),0) -> 0
A28: =J1 -> 0 | M28: =5*(COUNTIF(B28:L30,"5/0")+COUNTIF(B28:L30,"4/1")+COUNTIF(B28:L30,"3/2")+COUNTIF(B28:L30,"5/-"))+3*COUNTIF(B28:L30,"2/3")+2*COUNTIF(B28:L30,"1/4")+COUNTIF(B28:L30,"0/5")+0.01*N28+0.0001*(O28) -> 0 | N28: =1*COUNTIF(B28:L30,"5/0")+1*COUNTIF(B28:L30,"4/1")+1*COUNTIF(B28:L30,"3/2")+1*COUNTIF(B28:L30,"5/-")+0*COUNTIF(B28:L30,"2/3")+0*COUNTIF(B28:L30,"1/4")+0*COUNTIF(B28:L30,"0/5") -> 0 | O28: =5*COUNTIF(B28:L30,"5/0")+4*COUNTIF(B28:L30,"4/1")+3*COUNTIF(B28:L30,"3/2")+5*COUNTIF(B28:L30,"5/-")+2*COUNTIF(B28:L30,"2/3")+1*COUNTIF(B28:L30,"1/4")+0*COUNTIF(B28:L30,"0/5") -> 0 | P28: =0*COUNTIF(B28:L30,"5/0")+1*COUNTIF(B28:L30,"4/1")+2*COUNTIF(B28:L30,"3/2")+3*COUNTIF(B28:L30,"2/3")+4*COUNTIF(B28:L30,"1/4")+5*COUNTIF(B28:L30,"0/5")+5*COUNTIF(B28:L30,"-/5") -> 0 | Q28: =RANK(M28,M$4:M$36) -> 1
Q30: =IFERROR(M28/SUM(O28:P30),0) -> 0
A31: =K1 -> 0 | M31: =5*(COUNTIF(B31:L33,"5/0")+COUNTIF(B31:L33,"4/1")+COUNTIF(B31:L33,"3/2")+COUNTIF(B31:L33,"5/-"))+3*COUNTIF(B31:L33,"2/3")+2*COUNTIF(B31:L33,"1/4")+COUNTIF(B31:L33,"0/5")+0.01*N31+0.0001*(O31) -> 0 | N31: =1*COUNTIF(B31:L33,"5/0")+1*COUNTIF(B31:L33,"4/1")+1*COUNTIF(B31:L33,"3/2")+1*COUNTIF(B31:L33,"5/-")+0*COUNTIF(B31:L33,"2/3")+0*COUNTIF(B31:L33,"1/4")+0*COUNTIF(B31:L33,"0/5") -> 0 | O31: =5*COUNTIF(B31:L33,"5/0")+4*COUNTIF(B31:L33,"4/1")+3*COUNTIF(B31:L33,"3/2")+5*COUNTIF(B31:L33,"5/-")+2*COUNTIF(B31:L33,"2/3")+1*COUNTIF(B31:L33,"1/4")+0*COUNTIF(B31:L33,"0/5") -> 0 | P31: =0*COUNTIF(B31:L33,"5/0")+1*COUNTIF(B31:L33,"4/1")+2*COUNTIF(B31:L33,"3/2")+3*COUNTIF(B31:L33,"2/3")+4*COUNTIF(B31:L33,"1/4")+5*COUNTIF(B31:L33,"0/5")+5*COUNTIF(B31:L33,"-/5") -> 0 | Q31: =RANK(M31,M$4:M$36) -> 1
Q33: =IFERROR(M31/SUM(O31:P33),0) -> 0
A34: =L1 -> 0 | M34: =5*(COUNTIF(B34:L36,"5/0")+COUNTIF(B34:L36,"4/1")+COUNTIF(B34:L36,"3/2")+COUNTIF(B34:L36,"5/-"))+3*COUNTIF(B34:L36,"2/3")+2*COUNTIF(B34:L36,"1/4")+COUNTIF(B34:L36,"0/5")+0.01*N34+0.0001*(O34) -> 0 | N34: =1*COUNTIF(B34:L36,"5/0")+1*COUNTIF(B34:L36,"4/1")+1*COUNTIF(B34:L36,"3/2")+1*COUNTIF(B34:L36,"5/-")+0*COUNTIF(B34:L36,"2/3")+0*COUNTIF(B34:L36,"1/4")+0*COUNTIF(B34:L36,"0/5") -> 0 | O34: =5*COUNTIF(B34:L36,"5/0")+4*COUNTIF(B34:L36,"4/1")+3*COUNTIF(B34:L36,"3/2")+5*COUNTIF(B34:L36,"5/-")+2*COUNTIF(B34:L36,"2/3")+1*COUNTIF(B34:L36,"1/4")+0*COUNTIF(B34:L36,"0/5") -> 0 | P34: =0*COUNTIF(B34:L36,"5/0")+1*COUNTIF(B34:L36,"4/1")+2*COUNTIF(B34:L36,"3/2")+3*COUNTIF(B34:L36,"2/3")+4*COUNTIF(B34:L36,"1/4")+5*COUNTIF(B34:L36,"0/5")+5*COUNTIF(B34:L36,"-/5") -> 0 | Q34: =RANK(M34,M$4:M$36) -> 1
Q36: =IFERROR(M34/SUM(O34:P36),0) -> 0

Sheet D liga
B1: =VLOOKUP(CONCATENATE(LEFT($A$2,1),COLUMN()-1),nevezettek,3,FALSE) -> Bankits Csaba | C1: =VLOOKUP(CONCATENATE(LEFT($A$2,1),COLUMN()-1),nevezettek,3,FALSE) -> Makszin Miklós | D1: =VLOOKUP(CONCATENATE(LEFT($A$2,1),COLUMN()-1),nevezettek,3,FALSE) -> Bíró Zoltán | E1: =VLOOKUP(CONCATENATE(LEFT($A$2,1),COLUMN()-1),nevezettek,3,FALSE) -> Zsoldos Tamás | F1: =VLOOKUP(CONCATENATE(LEFT($A$2,1),COLUMN()-1),nevezettek,3,FALSE) -> Lukács Dániel | G1: =VLOOKUP(CONCATENATE(LEFT($A$2,1),COLUMN()-1),nevezettek,3,FALSE) -> Molnár Milán | H1: =VLOOKUP(CONCATENATE(LEFT($A$2,1),COLUMN()-1),nevezettek,3,FALSE) -> Bognár Barna | I1: =VLOOKUP(CONCATENATE(LEFT($A$2,1),COLUMN()-1),nevezettek,3,FALSE) -> Gáspár Júlia | ... L1: =VLOOKUP(CONCATENATE(LEFT($A$2,1),COLUMN()-1),nevezettek,3,FALSE) -> 0 | M1: összpont-szám | N1: Győze-lem | O1: Nyert szett | P1: Vesztett szett | Q1: helyezés (hatékonyság)
A2: =RIGHT(CELL("filename",A1),6) -> D liga
A3: =COUNTIF(Ligabeosztas!D:D,LEFT(A2,1)) -> 11
A4: =B1 -> Bankits Csaba | I4: 5/0 | M4: =5*(COUNTIF(B4:L6,"5/0")+COUNTIF(B4:L6,"4/1")+COUNTIF(B4:L6,"3/2")+COUNTIF(B4:L6,"5/-"))+3*COUNTIF(B4:L6,"2/3")+2*COUNTIF(B4:L6,"1/4")+COUNTIF(B4:L6,"0/5")+0.01*N4+0.0001*(O4) -> 5.0105 | N4: =1*COUNTIF(B4:L6,"5/0")+1*COUNTIF(B4:L6,"4/1")+1*COUNTIF(B4:L6,"3/2")+1*COUNTIF(B4:L6,"5/-")+0*COUNTIF(B4:L6,"2/3")+0*COUNTIF(B4:L6,"1/4")+0*COUNTIF(B4:L6,"0/5") -> 1 | O4: =5*COUNTIF(B4:L6,"5/0")+4*COUNTIF(B4:L6,"4/1")+3*COUNTIF(B4:L6,"3/2")+5*COUNTIF(B4:L6,"5/-")+2*COUNTIF(B4:L6,"2/3")+1*COUNTIF(B4:L6,"1/4")+0*COUNTIF(B4:L6,"0/5") -> 5 | P4: =0*COUNTIF(B4:L6,"5/0")+1*COUNTIF(B4:L6,"4/1")+2*COUNTIF(B4:L6,"3/2")+3*COUNTIF(B4:L6,"2/3")+4*COUNTIF(B4:L6,"1/4")+5*COUNTIF(B4:L6,"0/5")+5*COUNTIF(B4:L6,"-/5") -> 0 | Q4: =RANK(M4,M$4:M$36) -> 2
Q6: =IFERROR(M4/SUM(O4:P6),0) -> 1.0021
A7: =C1 -> Makszin Miklós | M7: =5*(COUNTIF(B7:L9,"5/0")+COUNTIF(B7:L9,"4/1")+COUNTIF(B7:L9,"3/2")+COUNTIF(B7:L9,"5/-"))+3*COUNTIF(B7:L9,"2/3")+2*COUNTIF(B7:L9,"1/4")+COUNTIF(B7:L9,"0/5")+0.01*N7+0.0001*(O7) -> 0 | N7: =1*COUNTIF(B7:L9,"5/0")+1*COUNTIF(B7:L9,"4/1")+1*COUNTIF(B7:L9,"3/2")+1*COUNTIF(B7:L9,"5/-")+0*COUNTIF(B7:L9,"2/3")+0*COUNTIF(B7:L9,"1/4")+0*COUNTIF(B7:L9,"0/5") -> 0 | O7: =5*COUNTIF(B7:L9,"5/0")+4*COUNTIF(B7:L9,"4/1")+3*COUNTIF(B7:L9,"3/2")+5*COUNTIF(B7:L9,"5/-")+2*COUNTIF(B7:L9,"2/3")+1*COUNTIF(B7:L9,"1/4")+0*COUNTIF(B7:L9,"0/5") -> 0 | P7: =0*COUNTIF(B7:L9,"5/0")+1*COUNTIF(B7:L9,"4/1")+2*COUNTIF(B7:L9,"3/2")+3*COUNTIF(B7:L9,"2/3")+4*COUNTIF(B7:L9,"1/4")+5*COUNTIF(B7:L9,"0/5")+5*COUNTIF(B7:L9,"-/5") -> 0 | Q7: =RANK(M7,M$4:M$36) -> 6
Q9: =IFERROR(M7/SUM(O7:P9),0) -> 0
A10: =D1 -> Bíró Zoltán | M10: =5*(COUNTIF(B10:L12,"5/0")+COUNTIF(B10:L12,"4/1")+COUNTIF(B10:L12,"3/2")+COUNTIF(B10:L12,"5/-"))+3*COUNTIF(B10:L12,"2/3")+2*COUNTIF(B10:L12,"1/4")+COUNTIF(B10:L12,"0/5")+0.01*N10+0.0001*(O10) -> 0 | N10: =1*COUNTIF(B10:L12,"5/0")+1*COUNTIF(B10:L12,"4/1")+1*COUNTIF(B10:L12,"3/2")+1*COUNTIF(B10:L12,"5/-")+0*COUNTIF(B10:L12,"2/3")+0*COUNTIF(B10:L12,"1/4")+0*COUNTIF(B10:L12,"0/5") -> 0 | O10: =5*COUNTIF(B10:L12,"5/0")+4*COUNTIF(B10:L12,"4/1")+3*COUNTIF(B10:L12,"3/2")+5*COUNTIF(B10:L12,"5/-")+2*COUNTIF(B10:L12,"2/3")+1*COUNTIF(B10:L12,"1/4")+0*COUNTIF(B10:L12,"0/5") -> 0 | P10: =0*COUNTIF(B10:L12,"5/0")+1*COUNTIF(B10:L12,"4/1")+2*COUNTIF(B10:L12,"3/2")+3*COUNTIF(B10:L12,"2/3")+4*COUNTIF(B10:L12,"1/4")+5*COUNTIF(B10:L12,"0/5")+5*COUNTIF(B10:L12,"-/5") -> 0 | Q10: =RANK(M10,M$4:M$36) -> 6
Q12: =IFERROR(M10/SUM(O10:P12),0) -> 0
A13: =E1 -> Zsoldos Tamás | G13: 5/0 | H13: 5/0 | M13: =5*(COUNTIF(B13:L15,"5/0")+COUNTIF(B13:L15,"4/1")+COUNTIF(B13:L15,"3/2")+COUNTIF(B13:L15,"5/-"))+3*COUNTIF(B13:L15,"2/3")+2*COUNTIF(B13:L15,"1/4")+COUNTIF(B13:L15,"0/5")+0.01*N13+0.0001*(O13) -> 10.021 | N13: =1*COUNTIF(B13:L15,"5/0")+1*COUNTIF(B13:L15,"4/1")+1*COUNTIF(B13:L15,"3/2")+1*COUNTIF(B13:L15,"5/-")+0*COUNTIF(B13:L15,"2/3")+0*COUNTIF(B13:L15,"1/4")+0*COUNTIF(B13:L15,"0/5") -> 2 | O13: =5*COUNTIF(B13:L15,"5/0")+4*COUNTIF(B13:L15,"4/1")+3*COUNTIF(B13:L15,"3/2")+5*COUNTIF(B13:L15,"5/-")+2*COUNTIF(B13:L15,"2/3")+1*COUNTIF(B13:L15,"1/4")+0*COUNTIF(B13:L15,"0/5") -> 10 | P13: =0*COUNTIF(B13:L15,"5/0")+1*COUNTIF(B13:L15,"4/1")+2*COUNTIF(B13:L15,"3/2")+3*COUNTIF(B13:L15,"2/3")+4*COUNTIF(B13:L15,"1/4")+5*COUNTIF(B13:L15,"0/5")+5*COUNTIF(B13:L15,"-/5") -> 0 | Q13: =RANK(M13,M$4:M$36) -> 1
Q15: =IFERROR(M13/SUM(O13:P15),0) -> 1.0021
A16: =F1 -> Lukács Dániel | M16: =5*(COUNTIF(B16:L18,"5/0")+COUNTIF(B16:L18,"4/1")+COUNTIF(B16:L18,"3/2")+COUNTIF(B16:L18,"5/-"))+3*COUNTIF(B16:L18,"2/3")+2*COUNTIF(B16:L18,"1/4")+COUNTIF(B16:L18,"0/5")+0.01*N16+0.0001*(O16) -> 0 | N16: =1*COUNTIF(B16:L18,"5/0")+1*COUNTIF(B16:L18,"4/1")+1*COUNTIF(B16:L18,"3/2")+1*COUNTIF(B16:L18,"5/-")+0*COUNTIF(B16:L18,"2/3")+0*COUNTIF(B16:L18,"1/4")+0*COUNTIF(B16:L18,"0/5") -> 0 | O16: =5*COUNTIF(B16:L18,"5/0")+4*COUNTIF(B16:L18,"4/1")+3*COUNTIF(B16:L18,"3/2")+5*COUNTIF(B16:L18,"5/-")+2*COUNTIF(B16:L18,"2/3")+1*COUNTIF(B16:L18,"1/4")+0*COUNTIF(B16:L18,"0/5") -> 0 | P16: =0*COUNTIF(B16:L18,"5/0")+1*COUNTIF(B16:L18,"4/1")+2*COUNTIF(B16:L18,"3/2")+3*COUNTIF(B16:L18,"2/3")+4*COUNTIF(B16:L18,"1/4")+5*COUNTIF(B16:L18,"0/5")+5*COUNTIF(B16:L18,"-/5") -> 0 | Q16: =RANK(M16,M$4:M$36) -> 6
Q18: =IFERROR(M16/SUM(O16:P18),0) -> 0
A19: =G1 -> Molnár Milán | E19: 0/5 | M19: =5*(COUNTIF(B19:L21,"5/0")+COUNTIF(B19:L21,"4/1")+COUNTIF(B19:L21,"3/2")+COUNTIF(B19:L21,"5/-"))+3*COUNTIF(B19:L21,"2/3")+2*COUNTIF(B19:L21,"1/4")+COUNTIF(B19:L21,"0/5")+0.01*N19+0.0001*(O19) -> 1 | N19: =1*COUNTIF(B19:L21,"5/0")+1*COUNTIF(B19:L21,"4/1")+1*COUNTIF(B19:L21,"3/2")+1*COUNTIF(B19:L21,"5/-")+0*COUNTIF(B19:L21,"2/3")+0*COUNTIF(B19:L21,"1/4")+0*COUNTIF(B19:L21,"0/5") -> 0 | O19: =5*COUNTIF(B19:L21,"5/0")+4*COUNTIF(B19:L21,"4/1")+3*COUNTIF(B19:L21,"3/2")+5*COUNTIF(B19:L21,"5/-")+2*COUNTIF(B19:L21,"2/3")+1*COUNTIF(B19:L21,"1/4")+0*COUNTIF(B19:L21,"0/5") -> 0 | P19: =0*COUNTIF(B19:L21,"5/0")+1*COUNTIF(B19:L21,"4/1")+2*COUNTIF(B19:L21,"3/2")+3*COUNTIF(B19:L21,"2/3")+4*COUNTIF(B19:L21,"1/4")+5*COUNTIF(B19:L21,"0/5")+5*COUNTIF(B19:L21,"-/5") -> 5 | Q19: =RANK(M19,M$4:M$36) -> 3
Q21: =IFERROR(M19/SUM(O19:P21),0) -> 0.2
A22: =H1 -> Bognár Barna | E22: 0/5 | M22: =5*(COUNTIF(B22:L24,"5/0")+COUNTIF(B22:L24,"4/1")+COUNTIF(B22:L24,"3/2")+COUNTIF(B22:L24,"5/-"))+3*COUNTIF(B22:L24,"2/3")+2*COUNTIF(B22:L24,"1/4")+COUNTIF(B22:L24,"0/5")+0.01*N22+0.0001*(O22) -> 1 | N22: =1*COUNTIF(B22:L24,"5/0")+1*COUNTIF(B22:L24,"4/1")+1*COUNTIF(B22:L24,"3/2")+1*COUNTIF(B22:L24,"5/-")+0*COUNTIF(B22:L24,"2/3")+0*COUNTIF(B22:L24,"1/4")+0*COUNTIF(B22:L24,"0/5") -> 0 | O22: =5*COUNTIF(B22:L24,"5/0")+4*COUNTIF(B22:L24,"4/1")+3*COUNTIF(B22:L24,"3/2")+5*COUNTIF(B22:L24,"5/-")+2*COUNTIF(B22:L24,"2/3")+1*COUNTIF(B22:L24,"1/4")+0*COUNTIF(B22:L24,"0/5") -> 0 | P22: =0*COUNTIF(B22:L24,"5/0")+1*COUNTIF(B22:L24,"4/1")+2*COUNTIF(B22:L24,"3/2")+3*COUNTIF(B22:L24,"2/3")+4*COUNTIF(B22:L24,"1/4")+5*COUNTIF(B22:L24,"0/5")+5*COUNTIF(B22:L24,"-/5") -> 5 | Q22: =RANK(M22,M$4:M$36) -> 3
Q24: =IFERROR(M22/SUM(O22:P24),0) -> 0.2
A25: =I1 -> Gáspár Júlia | B25: 0/5 | M25: =5*(COUNTIF(B25:L27,"5/0")+COUNTIF(B25:L27,"4/1")+COUNTIF(B25:L27,"3/2")+COUNTIF(B25:L27,"5/-"))+3*COUNTIF(B25:L27,"2/3")+2*COUNTIF(B25:L27,"1/4")+COUNTIF(B25:L27,"0/5")+0.01*N25+0.0001*(O25) -> 1 | N25: =1*COUNTIF(B25:L27,"5/0")+1*COUNTIF(B25:L27,"4/1")+1*COUNTIF(B25:L27,"3/2")+1*COUNTIF(B25:L27,"5/-")+0*COUNTIF(B25:L27,"2/3")+0*COUNTIF(B25:L27,"1/4")+0*COUNTIF(B25:L27,"0/5") -> 0 | O25: =5*COUNTIF(B25:L27,"5/0")+4*COUNTIF(B25:L27,"4/1")+3*COUNTIF(B25:L27,"3/2")+5*COUNTIF(B25:L27,"5/-")+2*COUNTIF(B25:L27,"2/3")+1*COUNTIF(B25:L27,"1/4")+0*COUNTIF(B25:L27,"0/5") -> 0 | P25: =0*COUNTIF(B25:L27,"5/0")+1*COUNTIF(B25:L27,"4/1")+2*COUNTIF(B25:L27,"3/2")+3*COUNTIF(B25:L27,"2/3")+4*COUNTIF(B25:L27,"1/4")+5*COUNTIF(B25:L27,"0/5")+5*COUNTIF(B25:L27,"-/5") -> 5 | Q25: =RANK(M25,M$4:M$36) -> 3
Q27: =IFERROR(M25/SUM(O25:P27),0) -> 0.2
A28: =J1 -> 0 | M28: =5*(COUNTIF(B28:L30,"5/0")+COUNTIF(B28:L30,"4/1")+COUNTIF(B28:L30,"3/2")+COUNTIF(B28:L30,"5/-"))+3*COUNTIF(B28:L30,"2/3")+2*COUNTIF(B28:L30,"1/4")+COUNTIF(B28:L30,"0/5")+0.01*N28+0.0001*(O28) -> 0 | N28: =1*COUNTIF(B28:L30,"5/0")+1*COUNTIF(B28:L30,"4/1")+1*COUNTIF(B28:L30,"3/2")+1*COUNTIF(B28:L30,"5/-")+0*COUNTIF(B28:L30,"2/3")+0*COUNTIF(B28:L30,"1/4")+0*COUNTIF(B28:L30,"0/5") -> 0 | O28: =5*COUNTIF(B28:L30,"5/0")+4*COUNTIF(B28:L30,"4/1")+3*COUNTIF(B28:L30,"3/2")+5*COUNTIF(B28:L30,"5/-")+2*COUNTIF(B28:L30,"2/3")+1*COUNTIF(B28:L30,"1/4")+0*COUNTIF(B28:L30,"0/5") -> 0 | P28: =0*COUNTIF(B28:L30,"5/0")+1*COUNTIF(B28:L30,"4/1")+2*COUNTIF(B28:L30,"3/2")+3*COUNTIF(B28:L30,"2/3")+4*COUNTIF(B28:L30,"1/4")+5*COUNTIF(B28:L30,"0/5")+5*COUNTIF(B28:L30,"-/5") -> 0 | Q28: =RANK(M28,M$4:M$36) -> 6
Q30: =IFERROR(M28/SUM(O28:P30),0) -> 0
A31: =K1 -> 0 | M31: =5*(COUNTIF(B31:L33,"5/0")+COUNTIF(B31:L33,"4/1")+COUNTIF(B31:L33,"3/2")+COUNTIF(B31:L33,"5/-"))+3*COUNTIF(B31:L33,"2/3")+2*COUNTIF(B31:L33,"1/4")+COUNTIF(B31:L33,"0/5")+0.01*N31+0.0001*(O31) -> 0 | N31: =1*COUNTIF(B31:L33,"5/0")+1*COUNTIF(B31:L33,"4/1")+1*COUNTIF(B31:L33,"3/2")+1*COUNTIF(B31:L33,"5/-")+0*COUNTIF(B31:L33,"2/3")+0*COUNTIF(B31:L33,"1/4")+0*COUNTIF(B31:L33,"0/5") -> 0 | O31: =5*COUNTIF(B31:L33,"5/0")+4*COUNTIF(B31:L33,"4/1")+3*COUNTIF(B31:L33,"3/2")+5*COUNTIF(B31:L33,"5/-")+2*COUNTIF(B31:L33,"2/3")+1*COUNTIF(B31:L33,"1/4")+0*COUNTIF(B31:L33,"0/5") -> 0 | P31: =0*COUNTIF(B31:L33,"5/0")+1*COUNTIF(B31:L33,"4/1")+2*COUNTIF(B31:L33,"3/2")+3*COUNTIF(B31:L33,"2/3")+4*COUNTIF(B31:L33,"1/4")+5*COUNTIF(B31:L33,"0/5")+5*COUNTIF(B31:L33,"-/5") -> 0 | Q31: =RANK(M31,M$4:M$36) -> 6
Q33: =IFERROR(M31/SUM(O31:P33),0) -> 0
A34: =L1 -> 0 | M34: =5*(COUNTIF(B34:L36,"5/0")+COUNTIF(B34:L36,"4/1")+COUNTIF(B34:L36,"3/2")+COUNTIF(B34:L36,"5/-"))+3*COUNTIF(B34:L36,"2/3")+2*COUNTIF(B34:L36,"1/4")+COUNTIF(B34:L36,"0/5")+0.01*N34+0.0001*(O34) -> 0 | N34: =1*COUNTIF(B34:L36,"5/0")+1*COUNTIF(B34:L36,"4/1")+1*COUNTIF(B34:L36,"3/2")+1*COUNTIF(B34:L36,"5/-")+0*COUNTIF(B34:L36,"2/3")+0*COUNTIF(B34:L36,"1/4")+0*COUNTIF(B34:L36,"0/5") -> 0 | O34: =5*COUNTIF(B34:L36,"5/0")+4*COUNTIF(B34:L36,"4/1")+3*COUNTIF(B34:L36,"3/2")+5*COUNTIF(B34:L36,"5/-")+2*COUNTIF(B34:L36,"2/3")+1*COUNTIF(B34:L36,"1/4")+0*COUNTIF(B34:L36,"0/5") -> 0 | P34: =0*COUNTIF(B34:L36,"5/0")+1*COUNTIF(B34:L36,"4/1")+2*COUNTIF(B34:L36,"3/2")+3*COUNTIF(B34:L36,"2/3")+4*COUNTIF(B34:L36,"1/4")+5*COUNTIF(B34:L36,"0/5")+5*COUNTIF(B34:L36,"-/5") -> 0 | Q34: =RANK(M34,M$4:M$36) -> 6
Q36: =IFERROR(M34/SUM(O34:P36),0) -> 0

Sheet E liga
B1: =VLOOKUP(CONCATENATE(LEFT($A$2,1),COLUMN()-1),nevezettek,3,FALSE) -> Bakos Mátyás | C1: =VLOOKUP(CONCATENATE(LEFT($A$2,1),COLUMN()-1),nevezettek,3,FALSE) -> Szerdahelyi Dániel | D1: =VLOOKUP(CONCATENATE(LEFT($A$2,1),COLUMN()-1),nevezettek,3,FALSE) -> Vincze Krisztián | E1: =VLOOKUP(CONCATENATE(LEFT($A$2,1),COLUMN()-1),nevezettek,3,FALSE) -> Hajba Tibor | F1: =VLOOKUP(CONCATENATE(LEFT($A$2,1),COLUMN()-1),nevezettek,3,FALSE) -> Hajba Zoé | G1: =VLOOKUP(CONCATENATE(LEFT($A$2,1),COLUMN()-1),nevezettek,3,FALSE) -> Kovács Zsolt | H1: =VLOOKUP(CONCATENATE(LEFT($A$2,1),COLUMN()-1),nevezettek,3,FALSE) -> Szekeres Martin | I1: =VLOOKUP(CONCATENATE(LEFT($A$2,1),COLUMN()-1),nevezettek,3,FALSE) -> Némeh Balázs | J1: =VLOOKUP(CONCATENATE(LEFT($A$2,1),COLUMN()-1),nevezettek,3,FALSE) -> Nagy Zoltán | K1: összpont-szám | L1: Győze-lem | M1: Nyert szett | N1: Vesztett szett | O1: helyezés (hatékonyság)
A2: =RIGHT(CELL("filename",A1),6) -> E liga
A3: =COUNTIF(Ligabeosztas!D:D,LEFT(A2,1)) -> 9
A4: =B1 -> Bakos Mátyás | C4: 2/3 | F4: 4/1 | K4: =5*(COUNTIF(B4:J6,"5/0")+COUNTIF(B4:J6,"4/1")+COUNTIF(B4:J6,"3/2")+COUNTIF(B4:J6,"5/-"))+3*COUNTIF(B4:J6,"2/3")+2*COUNTIF(B4:J6,"1/4")+COUNTIF(B4:J6,"0/5")+0.01*L4+0.0001*(M4) -> 8.0106 | L4: =1*COUNTIF(B4:J6,"5/0")+1*COUNTIF(B4:J6,"4/1")+1*COUNTIF(B4:J6,"3/2")+1*COUNTIF(B4:J6,"5/-")+0*COUNTIF(B4:J6,"2/3")+0*COUNTIF(B4:J6,"1/4")+0*COUNTIF(B4:J6,"0/5") -> 1 | M4: =5*COUNTIF(B4:J6,"5/0")+4*COUNTIF(B4:J6,"4/1")+3*COUNTIF(B4:J6,"3/2")+5*COUNTIF(B4:J6,"5/-")+2*COUNTIF(B4:J6,"2/3")+1*COUNTIF(B4:J6,"1/4")+0*COUNTIF(B4:J6,"0/5") -> 6 | N4: =0*COUNTIF(B4:J6,"5/0")+1*COUNTIF(B4:J6,"4/1")+2*COUNTIF(B4:J6,"3/2")+3*COUNTIF(B4:J6,"2/3")+4*COUNTIF(B4:J6,"1/4")+5*COUNTIF(B4:J6,"0/5")+5*COUNTIF(B4:J6,"-/5") -> 4 | O4: =RANK(K4,K$4:K$30) -> 4
O6: =IFERROR(K4/SUM(M4:N6),0) -> 0.80106
A7: =C1 -> Szerdahelyi Dániel | B7: 3/2 | D7: 3/2 | H7: 3/2 | K7: =5*(COUNTIF(B7:J9,"5/0")+COUNTIF(B7:J9,"4/1")+COUNTIF(B7:J9,"3/2")+COUNTIF(B7:J9,"5/-"))+3*COUNTIF(B7:J9,"2/3")+2*COUNTIF(B7:J9,"1/4")+COUNTIF(B7:J9,"0/5")+0.01*L7+0.0001*(M7) -> 15.0309 | L7: =1*COUNTIF(B7:J9,"5/0")+1*COUNTIF(B7:J9,"4/1")+1*COUNTIF(B7:J9,"3/2")+1*COUNTIF(B7:J9,"5/-")+0*COUNTIF(B7:J9,"2/3")+0*COUNTIF(B7:J9,"1/4")+0*COUNTIF(B7:J9,"0/5") -> 3 | M7: =5*COUNTIF(B7:J9,"5/0")+4*COUNTIF(B7:J9,"4/1")+3*COUNTIF(B7:J9,"3/2")+5*COUNTIF(B7:J9,"5/-")+2*COUNTIF(B7:J9,"2/3")+1*COUNTIF(B7:J9,"1/4")+0*COUNTIF(B7:J9,"0/5") -> 9 | N7: =0*COUNTIF(B7:J9,"5/0")+1*COUNTIF(B7:J9,"4/1")+2*COUNTIF(B7:J9,"3/2")+3*COUNTIF(B7:J9,"2/3")+4*COUNTIF(B7:J9,"1/4")+5*COUNTIF(B7:J9,"0/5")+5*COUNTIF(B7:J9,"-/5") -> 6 | O7: =RANK(K7,K$4:K$30) -> 1
O9: =IFERROR(K7/SUM(M7:N9),0) -> 1.00206
A10: =D1 -> Vincze Krisztián | C10: 2/3 | E10: 4/1 | F10: 3/2 | K10: =5*(COUNTIF(B10:J12,"5/0")+COUNTIF(B10:J12,"4/1")+COUNTIF(B10:J12,"3/2")+COUNTIF(B10:J12,"5/-"))+3*COUNTIF(B10:J12,"2/3")+2*COUNTIF(B10:J12,"1/4")+COUNTIF(B10:J12,"0/5")+0.01*L10+0.0001*(M10) -> 13.0209 | L10: =1*COUNTIF(B10:J12,"5/0")+1*COUNTIF(B10:J12,"4/1")+1*COUNTIF(B10:J12,"3/2")+1*COUNTIF(B10:J12,"5/-")+0*COUNTIF(B10:J12,"2/3")+0*COUNTIF(B10:J12,"1/4")+0*COUNTIF(B10:J12,"0/5") -> 2 | M10: =5*COUNTIF(B10:J12,"5/0")+4*COUNTIF(B10:J12,"4/1")+3*COUNTIF(B10:J12,"3/2")+5*COUNTIF(B10:J12,"5/-")+2*COUNTIF(B10:J12,"2/3")+1*COUNTIF(B10:J12,"1/4")+0*COUNTIF(B10:J12,"0/5") -> 9 | N10: =0*COUNTIF(B10:J12,"5/0")+1*COUNTIF(B10:J12,"4/1")+2*COUNTIF(B10:J12,"3/2")+3*COUNTIF(B10:J12,"2/3")+4*COUNTIF(B10:J12,"1/4")+5*COUNTIF(B10:J12,"0/5")+5*COUNTIF(B10:J12,"-/5") -> 6 | O10: =RANK(K10,K$4:K$30) -> 2
O12: =IFERROR(K10/SUM(M10:N12),0) -> 0.86806
A13: =E1 -> Hajba Tibor | D13: 1/4 | I13: 1/4 | K13: =5*(COUNTIF(B13:J15,"5/0")+COUNTIF(B13:J15,"4/1")+COUNTIF(B13:J15,"3/2")+COUNTIF(B13:J15,"5/-"))+3*COUNTIF(B13:J15,"2/3")+2*COUNTIF(B13:J15,"1/4")+COUNTIF(B13:J15,"0/5")+0.01*L13+0.0001*(M13) -> 4.0002 | L13: =1*COUNTIF(B13:J15,"5/0")+1*COUNTIF(B13:J15,"4/1")+1*COUNTIF(B13:J15,"3/2")+1*COUNTIF(B13:J15,"5/-")+0*COUNTIF(B13:J15,"2/3")+0*COUNTIF(B13:J15,"1/4")+0*COUNTIF(B13:J15,"0/5") -> 0 | M13: =5*COUNTIF(B13:J15,"5/0")+4*COUNTIF(B13:J15,"4/1")+3*COUNTIF(B13:J15,"3/2")+5*COUNTIF(B13:J15,"5/-")+2*COUNTIF(B13:J15,"2/3")+1*COUNTIF(B13:J15,"1/4")+0*COUNTIF(B13:J15,"0/5") -> 2 | N13: =0*COUNTIF(B13:J15,"5/0")+1*COUNTIF(B13:J15,"4/1")+2*COUNTIF(B13:J15,"3/2")+3*COUNTIF(B13:J15,"2/3")+4*COUNTIF(B13:J15,"1/4")+5*COUNTIF(B13:J15,"0/5")+5*COUNTIF(B13:J15,"-/5") -> 8 | O13: =RANK(K13,K$4:K$30) -> 6
O15: =IFERROR(K13/SUM(M13:N15),0) -> 0.40002
A16: =F1 -> Hajba Zoé | B16: 1/4 | D16: 2/3 | K16: =5*(COUNTIF(B16:J18,"5/0")+COUNTIF(B16:J18,"4/1")+COUNTIF(B16:J18,"3/2")+COUNTIF(B16:J18,"5/-"))+3*COUNTIF(B16:J18,"2/3")+2*COUNTIF(B16:J18,"1/4")+COUNTIF(B16:J18,"0/5")+0.01*L16+0.0001*(M16) -> 5.0003 | L16: =1*COUNTIF(B16:J18,"5/0")+1*COUNTIF(B16:J18,"4/1")+1*COUNTIF(B16:J18,"3/2")+1*COUNTIF(B16:J18,"5/-")+0*COUNTIF(B16:J18,"2/3")+0*COUNTIF(B16:J18,"1/4")+0*COUNTIF(B16:J18,"0/5") -> 0 | M16: =5*COUNTIF(B16:J18,"5/0")+4*COUNTIF(B16:J18,"4/1")+3*COUNTIF(B16:J18,"3/2")+5*COUNTIF(B16:J18,"5/-")+2*COUNTIF(B16:J18,"2/3")+1*COUNTIF(B16:J18,"1/4")+0*COUNTIF(B16:J18,"0/5") -> 3 | N16: =0*COUNTIF(B16:J18,"5/0")+1*COUNTIF(B16:J18,"4/1")+2*COUNTIF(B16:J18,"3/2")+3*COUNTIF(B16:J18,"2/3")+4*COUNTIF(B16:J18,"1/4")+5*COUNTIF(B16:J18,"0/5")+5*COUNTIF(B16:J18,"-/5") -> 7 | O16: =RANK(K16,K$4:K$30) -> 5
O18: =IFERROR(K16/SUM(M16:N18),0) -> 0.50003
A19: =G1 -> Kovács Zsolt | K19: =5*(COUNTIF(B19:J21,"5/0")+COUNTIF(B19:J21,"4/1")+COUNTIF(B19:J21,"3/2")+COUNTIF(B19:J21,"5/-"))+3*COUNTIF(B19:J21,"2/3")+2*COUNTIF(B19:J21,"1/4")+COUNTIF(B19:J21,"0/5")+0.01*L19+0.0001*(M19) -> 0 | L19: =1*COUNTIF(B19:J21,"5/0")+1*COUNTIF(B19:J21,"4/1")+1*COUNTIF(B19:J21,"3/2")+1*COUNTIF(B19:J21,"5/-")+0*COUNTIF(B19:J21,"2/3")+0*COUNTIF(B19:J21,"1/4")+0*COUNTIF(B19:J21,"0/5") -> 0 | M19: =5*COUNTIF(B19:J21,"5/0")+4*COUNTIF(B19:J21,"4/1")+3*COUNTIF(B19:J21,"3/2")+5*COUNTIF(B19:J21,"5/-")+2*COUNTIF(B19:J21,"2/3")+1*COUNTIF(B19:J21,"1/4")+0*COUNTIF(B19:J21,"0/5") -> 0 | N19: =0*COUNTIF(B19:J21,"5/0")+1*COUNTIF(B19:J21,"4/1")+2*COUNTIF(B19:J21,"3/2")+3*COUNTIF(B19:J21,"2/3")+4*COUNTIF(B19:J21,"1/4")+5*COUNTIF(B19:J21,"0/5")+5*COUNTIF(B19:J21,"-/5") -> 0 | O19: =RANK(K19,K$4:K$30) -> 9
O21: =IFERROR(K19/SUM(M19:N21),0) -> 0
A22: =H1 -> Szekeres Martin | C22: 2/3 | K22: =5*(COUNTIF(B22:J24,"5/0")+COUNTIF(B22:J24,"4/1")+COUNTIF(B22:J24,"3/2")+COUNTIF(B22:J24,"5/-"))+3*COUNTIF(B22:J24,"2/3")+2*COUNTIF(B22:J24,"1/4")+COUNTIF(B22:J24,"0/5")+0.01*L22+0.0001*(M22) -> 3.0002 | L22: =1*COUNTIF(B22:J24,"5/0")+1*COUNTIF(B22:J24,"4/1")+1*COUNTIF(B22:J24,"3/2")+1*COUNTIF(B22:J24,"5/-")+0*COUNTIF(B22:J24,"2/3")+0*COUNTIF(B22:J24,"1/4")+0*COUNTIF(B22:J24,"0/5") -> 0 | M22: =5*COUNTIF(B22:J24,"5/0")+4*COUNTIF(B22:J24,"4/1")+3*COUNTIF(B22:J24,"3/2")+5*COUNTIF(B22:J24,"5/-")+2*COUNTIF(B22:J24,"2/3")+1*COUNTIF(B22:J24,"1/4")+0*COUNTIF(B22:J24,"0/5") -> 2 | N22: =0*COUNTIF(B22:J24,"5/0")+1*COUNTIF(B22:J24,"4/1")+2*COUNTIF(B22:J24,"3/2")+3*COUNTIF(B22:J24,"2/3")+4*COUNTIF(B22:J24,"1/4")+5*COUNTIF(B22:J24,"0/5")+5*COUNTIF(B22:J24,"-/5") -> 3 | O22: =RANK(K22,K$4:K$30) -> 7
O24: =IFERROR(K22/SUM(M22:N24),0) -> 0.60004
A25: =I1 -> Némeh Balázs | E25: 4/1 | J25: 5/0 | K25: =5*(COUNTIF(B25:J27,"5/0")+COUNTIF(B25:J27,"4/1")+COUNTIF(B25:J27,"3/2")+COUNTIF(B25:J27,"5/-"))+3*COUNTIF(B25:J27,"2/3")+2*COUNTIF(B25:J27,"1/4")+COUNTIF(B25:J27,"0/5")+0.01*L25+0.0001*(M25) -> 10.0209 | L25: =1*COUNTIF(B25:J27,"5/0")+1*COUNTIF(B25:J27,"4/1")+1*COUNTIF(B25:J27,"3/2")+1*COUNTIF(B25:J27,"5/-")+0*COUNTIF(B25:J27,"2/3")+0*COUNTIF(B25:J27,"1/4")+0*COUNTIF(B25:J27,"0/5") -> 2 | M25: =5*COUNTIF(B25:J27,"5/0")+4*COUNTIF(B25:J27,"4/1")+3*COUNTIF(B25:J27,"3/2")+5*COUNTIF(B25:J27,"5/-")+2*COUNTIF(B25:J27,"2/3")+1*COUNTIF(B25:J27,"1/4")+0*COUNTIF(B25:J27,"0/5") -> 9 | N25: =0*COUNTIF(B25:J27,"5/0")+1*COUNTIF(B25:J27,"4/1")+2*COUNTIF(B25:J27,"3/2")+3*COUNTIF(B25:J27,"2/3")+4*COUNTIF(B25:J27,"1/4")+5*COUNTIF(B25:J27,"0/5")+5*COUNTIF(B25:J27,"-/5") -> 1 | O25: =RANK(K25,K$4:K$30) -> 3
O27: =IFERROR(K25/SUM(M25:N27),0) -> 1.00209
A28: =J1 -> Nagy Zoltán | I28: 0/5 | K28: =5*(COUNTIF(B28:J30,"5/0")+COUNTIF(B28:J30,"4/1")+COUNTIF(B28:J30,"3/2")+COUNTIF(B28:J30,"5/-"))+3*COUNTIF(B28:J30,"2/3")+2*COUNTIF(B28:J30,"1/4")+COUNTIF(B28:J30,"0/5")+0.01*L28+0.0001*(M28) -> 1 | L28: =1*COUNTIF(B28:J30,"5/0")+1*COUNTIF(B28:J30,"4/1")+1*COUNTIF(B28:J30,"3/2")+1*COUNTIF(B28:J30,"5/-")+0*COUNTIF(B28:J30,"2/3")+0*COUNTIF(B28:J30,"1/4")+0*COUNTIF(B28:J30,"0/5") -> 0 | M28: =5*COUNTIF(B28:J30,"5/0")+4*COUNTIF(B28:J30,"4/1")+3*COUNTIF(B28:J30,"3/2")+5*COUNTIF(B28:J30,"5/-")+2*COUNTIF(B28:J30,"2/3")+1*COUNTIF(B28:J30,"1/4")+0*COUNTIF(B28:J30,"0/5") -> 0 | N28: =0*COUNTIF(B28:J30,"5/0")+1*COUNTIF(B28:J30,"4/1")+2*COUNTIF(B28:J30,"3/2")+3*COUNTIF(B28:J30,"2/3")+4*COUNTIF(B28:J30,"1/4")+5*COUNTIF(B28:J30,"0/5")+5*COUNTIF(B28:J30,"-/5") -> 5 | O28: =RANK(K28,K$4:K$30) -> 8
O30: =IFERROR(K28/SUM(M28:N30),0) -> 0.2

Sheet F liga
B1: =VLOOKUP(CONCATENATE(LEFT($A$2,1),COLUMN()-1),nevezettek,3,FALSE) -> 0 | C1: =VLOOKUP(CONCATENATE(LEFT($A$2,1),COLUMN()-1),nevezettek,3,FALSE) -> 0 | D1: =VLOOKUP(CONCATENATE(LEFT($A$2,1),COLUMN()-1),nevezettek,3,FALSE) -> 0 | E1: =VLOOKUP(CONCATENATE(LEFT($A$2,1),COLUMN()-1),nevezettek,3,FALSE) -> 0 | F1: =VLOOKUP(CONCATENATE(LEFT($A$2,1),COLUMN()-1),nevezettek,3,FALSE) -> 0 | G1: =VLOOKUP(CONCATENATE(LEFT($A$2,1),COLUMN()-1),nevezettek,3,FALSE) -> 0 | H1: =VLOOKUP(CONCATENATE(LEFT($A$2,1),COLUMN()-1),nevezettek,3,FALSE) -> 0 | I1: =VLOOKUP(CONCATENATE(LEFT($A$2,1),COLUMN()-1),nevezettek,3,FALSE) -> 0 | J1: =VLOOKUP(CONCATENATE(LEFT($A$2,1),COLUMN()-1),nevezettek,3,FALSE) -> #N/A | K1: összpont-szám | L1: Győze-lem | M1: Nyert szett | N1: Vesztett szett | O1: helyezés (hatékonyság)
A2: =RIGHT(CELL("filename",A1),6) -> F liga
A3: =COUNTIF(Ligabeosztas!D:D,LEFT(A2,1)) -> 8
A4: =B1 -> 0 | K4: =5*(COUNTIF(B4:J6,"5/0")+COUNTIF(B4:J6,"4/1")+COUNTIF(B4:J6,"3/2")+COUNTIF(B4:J6,"5/-"))+3*COUNTIF(B4:J6,"2/3")+2*COUNTIF(B4:J6,"1/4")+COUNTIF(B4:J6,"0/5")+0.01*L4+0.0001*(M4) -> 0 | L4: =1*COUNTIF(B4:J6,"5/0")+1*COUNTIF(B4:J6,"4/1")+1*COUNTIF(B4:J6,"3/2")+1*COUNTIF(B4:J6,"5/-")+0*COUNTIF(B4:J6,"2/3")+0*COUNTIF(B4:J6,"1/4")+0*COUNTIF(B4:J6,"0/5") -> 0 | M4: =5*COUNTIF(B4:J6,"5/0")+4*COUNTIF(B4:J6,"4/1")+3*COUNTIF(B4:J6,"3/2")+5*COUNTIF(B4:J6,"5/-")+2*COUNTIF(B4:J6,"2/3")+1*COUNTIF(B4:J6,"1/4")+0*COUNTIF(B4:J6,"0/5") -> 0 | N4: =0*COUNTIF(B4:J6,"5/0")+1*COUNTIF(B4:J6,"4/1")+2*COUNTIF(B4:J6,"3/2")+3*COUNTIF(B4:J6,"2/3")+4*COUNTIF(B4:J6,"1/4")+5*COUNTIF(B4:J6,"0/5")+5*COUNTIF(B4:J6,"-/5") -> 0 | O4: =RANK(K4,K$4:K$30) -> 1
O6: =IFERROR(K4/SUM(M4:N6),0) -> 0
A7: =C1 -> 0 | K7: =5*(COUNTIF(B7:J9,"5/0")+COUNTIF(B7:J9,"4/1")+COUNTIF(B7:J9,"3/2")+COUNTIF(B7:J9,"5/-"))+3*COUNTIF(B7:J9,"2/3")+2*COUNTIF(B7:J9,"1/4")+COUNTIF(B7:J9,"0/5")+0.01*L7+0.0001*(M7) -> 0 | L7: =1*COUNTIF(B7:J9,"5/0")+1*COUNTIF(B7:J9,"4/1")+1*COUNTIF(B7:J9,"3/2")+1*COUNTIF(B7:J9,"5/-")+0*COUNTIF(B7:J9,"2/3")+0*COUNTIF(B7:J9,"1/4")+0*COUNTIF(B7:J9,"0/5") -> 0 | M7: =5*COUNTIF(B7:J9,"5/0")+4*COUNTIF(B7:J9,"4/1")+3*COUNTIF(B7:J9,"3/2")+5*COUNTIF(B7:J9,"5/-")+2*COUNTIF(B7:J9,"2/3")+1*COUNTIF(B7:J9,"1/4")+0*COUNTIF(B7:J9,"0/5") -> 0 | N7: =0*COUNTIF(B7:J9,"5/0")+1*COUNTIF(B7:J9,"4/1")+2*COUNTIF(B7:J9,"3/2")+3*COUNTIF(B7:J9,"2/3")+4*COUNTIF(B7:J9,"1/4")+5*COUNTIF(B7:J9,"0/5")+5*COUNTIF(B7:J9,"-/5") -> 0 | O7: =RANK(K7,K$4:K$30) -> 1
O9: =IFERROR(K7/SUM(M7:N9),0) -> 0
A10: =D1 -> 0 | K10: =5*(COUNTIF(B10:J12,"5/0")+COUNTIF(B10:J12,"4/1")+COUNTIF(B10:J12,"3/2")+COUNTIF(B10:J12,"5/-"))+3*COUNTIF(B10:J12,"2/3")+2*COUNTIF(B10:J12,"1/4")+COUNTIF(B10:J12,"0/5")+0.01*L10+0.0001*(M10) -> 0 | L10: =1*COUNTIF(B10:J12,"5/0")+1*COUNTIF(B10:J12,"4/1")+1*COUNTIF(B10:J12,"3/2")+1*COUNTIF(B10:J12,"5/-")+0*COUNTIF(B10:J12,"2/3")+0*COUNTIF(B10:J12,"1/4")+0*COUNTIF(B10:J12,"0/5") -> 0 | M10: =5*COUNTIF(B10:J12,"5/0")+4*COUNTIF(B10:J12,"4/1")+3*COUNTIF(B10:J12,"3/2")+5*COUNTIF(B10:J12,"5/-")+2*COUNTIF(B10:J12,"2/3")+1*COUNTIF(B10:J12,"1/4")+0*COUNTIF(B10:J12,"0/5") -> 0 | N10: =0*COUNTIF(B10:J12,"5/0")+1*COUNTIF(B10:J12,"4/1")+2*COUNTIF(B10:J12,"3/2")+3*COUNTIF(B10:J12,"2/3")+4*COUNTIF(B10:J12,"1/4")+5*COUNTIF(B10:J12,"0/5")+5*COUNTIF(B10:J12,"-/5") -> 0 | O10: =RANK(K10,K$4:K$30) -> 1
O12: =IFERROR(K10/SUM(M10:N12),0) -> 0
A13: =E1 -> 0 | K13: =5*(COUNTIF(B13:J15,"5/0")+COUNTIF(B13:J15,"4/1")+COUNTIF(B13:J15,"3/2")+COUNTIF(B13:J15,"5/-"))+3*COUNTIF(B13:J15,"2/3")+2*COUNTIF(B13:J15,"1/4")+COUNTIF(B13:J15,"0/5")+0.01*L13+0.0001*(M13) -> 0 | L13: =1*COUNTIF(B13:J15,"5/0")+1*COUNTIF(B13:J15,"4/1")+1*COUNTIF(B13:J15,"3/2")+1*COUNTIF(B13:J15,"5/-")+0*COUNTIF(B13:J15,"2/3")+0*COUNTIF(B13:J15,"1/4")+0*COUNTIF(B13:J15,"0/5") -> 0 | M13: =5*COUNTIF(B13:J15,"5/0")+4*COUNTIF(B13:J15,"4/1")+3*COUNTIF(B13:J15,"3/2")+5*COUNTIF(B13:J15,"5/-")+2*COUNTIF(B13:J15,"2/3")+1*COUNTIF(B13:J15,"1/4")+0*COUNTIF(B13:J15,"0/5") -> 0 | N13: =0*COUNTIF(B13:J15,"5/0")+1*COUNTIF(B13:J15,"4/1")+2*COUNTIF(B13:J15,"3/2")+3*COUNTIF(B13:J15,"2/3")+4*COUNTIF(B13:J15,"1/4")+5*COUNTIF(B13:J15,"0/5")+5*COUNTIF(B13:J15,"-/5") -> 0 | O13: =RANK(K13,K$4:K$30) -> 1
O15: =IFERROR(K13/SUM(M13:N15),0) -> 0
A16: =F1 -> 0 | K16: =5*(COUNTIF(B16:J18,"5/0")+COUNTIF(B16:J18,"4/1")+COUNTIF(B16:J18,"3/2")+COUNTIF(B16:J18,"5/-"))+3*COUNTIF(B16:J18,"2/3")+2*COUNTIF(B16:J18,"1/4")+COUNTIF(B16:J18,"0/5")+0.01*L16+0.0001*(M16) -> 0 | L16: =1*COUNTIF(B16:J18,"5/0")+1*COUNTIF(B16:J18,"4/1")+1*COUNTIF(B16:J18,"3/2")+1*COUNTIF(B16:J18,"5/-")+0*COUNTIF(B16:J18,"2/3")+0*COUNTIF(B16:J18,"1/4")+0*COUNTIF(B16:J18,"0/5") -> 0 | M16: =5*COUNTIF(B16:J18,"5/0")+4*COUNTIF(B16:J18,"4/1")+3*COUNTIF(B16:J18,"3/2")+5*COUNTIF(B16:J18,"5/-")+2*COUNTIF(B16:J18,"2/3")+1*COUNTIF(B16:J18,"1/4")+0*COUNTIF(B16:J18,"0/5") -> 0 | N16: =0*COUNTIF(B16:J18,"5/0")+1*COUNTIF(B16:J18,"4/1")+2*COUNTIF(B16:J18,"3/2")+3*COUNTIF(B16:J18,"2/3")+4*COUNTIF(B16:J18,"1/4")+5*COUNTIF(B16:J18,"0/5")+5*COUNTIF(B16:J18,"-/5") -> 0 | O16: =RANK(K16,K$4:K$30) -> 1
O18: =IFERROR(K16/SUM(M16:N18),0) -> 0
A19: =G1 -> 0 | K19: =5*(COUNTIF(B19:J21,"5/0")+COUNTIF(B19:J21,"4/1")+COUNTIF(B19:J21,"3/2")+COUNTIF(B19:J21,"5/-"))+3*COUNTIF(B19:J21,"2/3")+2*COUNTIF(B19:J21,"1/4")+COUNTIF(B19:J21,"0/5")+0.01*L19+0.0001*(M19) -> 0 | L19: =1*COUNTIF(B19:J21,"5/0")+1*COUNTIF(B19:J21,"4/1")+1*COUNTIF(B19:J21,"3/2")+1*COUNTIF(B19:J21,"5/-")+0*COUNTIF(B19:J21,"2/3")+0*COUNTIF(B19:J21,"1/4")+0*COUNTIF(B19:J21,"0/5") -> 0 | M19: =5*COUNTIF(B19:J21,"5/0")+4*COUNTIF(B19:J21,"4/1")+3*COUNTIF(B19:J21,"3/2")+5*COUNTIF(B19:J21,"5/-")+2*COUNTIF(B19:J21,"2/3")+1*COUNTIF(B19:J21,"1/4")+0*COUNTIF(B19:J21,"0/5") -> 0 | N19: =0*COUNTIF(B19:J21,"5/0")+1*COUNTIF(B19:J21,"4/1")+2*COUNTIF(B19:J21,"3/2")+3*COUNTIF(B19:J21,"2/3")+4*COUNTIF(B19:J21,"1/4")+5*COUNTIF(B19:J21,"0/5")+5*COUNTIF(B19:J21,"-/5") -> 0 | O19: =RANK(K19,K$4:K$30) -> 1
O21: =IFERROR(K19/SUM(M19:N21),0) -> 0
A22: =H1 -> 0 | K22: =5*(COUNTIF(B22:J24,"5/0")+COUNTIF(B22:J24,"4/1")+COUNTIF(B22:J24,"3/2")+COUNTIF(B22:J24,"5/-"))+3*COUNTIF(B22:J24,"2/3")+2*COUNTIF(B22:J24,"1/4")+COUNTIF(B22:J24,"0/5")+0.01*L22+0.0001*(M22) -> 0 | L22: =1*COUNTIF(B22:J24,"5/0")+1*COUNTIF(B22:J24,"4/1")+1*COUNTIF(B22:J24,"3/2")+1*COUNTIF(B22:J24,"5/-")+0*COUNTIF(B22:J24,"2/3")+0*COUNTIF(B22:J24,"1/4")+0*COUNTIF(B22:J24,"0/5") -> 0 | M22: =5*COUNTIF(B22:J24,"5/0")+4*COUNTIF(B22:J24,"4/1")+3*COUNTIF(B22:J24,"3/2")+5*COUNTIF(B22:J24,"5/-")+2*COUNTIF(B22:J24,"2/3")+1*COUNTIF(B22:J24,"1/4")+0*COUNTIF(B22:J24,"0/5") -> 0 | N22: =0*COUNTIF(B22:J24,"5/0")+1*COUNTIF(B22:J24,"4/1")+2*COUNTIF(B22:J24,"3/2")+3*COUNTIF(B22:J24,"2/3")+4*COUNTIF(B22:J24,"1/4")+5*COUNTIF(B22:J24,"0/5")+5*COUNTIF(B22:J24,"-/5") -> 0 | O22: =RANK(K22,K$4:K$30) -> 1
O24: =IFERROR(K22/SUM(M22:N24),0) -> 0
A25: =I1 -> 0 | K25: =5*(COUNTIF(B25:J27,"5/0")+COUNTIF(B25:J27,"4/1")+COUNTIF(B25:J27,"3/2")+COUNTIF(B25:J27,"5/-"))+3*COUNTIF(B25:J27,"2/3")+2*COUNTIF(B25:J27,"1/4")+COUNTIF(B25:J27,"0/5")+0.01*L25+0.0001*(M25) -> 0 | L25: =1*COUNTIF(B25:J27,"5/0")+1*COUNTIF(B25:J27,"4/1")+1*COUNTIF(B25:J27,"3/2")+1*COUNTIF(B25:J27,"5/-")+0*COUNTIF(B25:J27,"2/3")+0*COUNTIF(B25:J27,"1/4")+0*COUNTIF(B25:J27,"0/5") -> 0 | M25: =5*COUNTIF(B25:J27,"5/0")+4*COUNTIF(B25:J27,"4/1")+3*COUNTIF(B25:J27,"3/2")+5*COUNTIF(B25:J27,"5/-")+2*COUNTIF(B25:J27,"2/3")+1*COUNTIF(B25:J27,"1/4")+0*COUNTIF(B25:J27,"0/5") -> 0 | N25: =0*COUNTIF(B25:J27,"5/0")+1*COUNTIF(B25:J27,"4/1")+2*COUNTIF(B25:J27,"3/2")+3*COUNTIF(B25:J27,"2/3")+4*COUNTIF(B25:J27,"1/4")+5*COUNTIF(B25:J27,"0/5")+5*COUNTIF(B25:J27,"-/5") -> 0 | O25: =RANK(K25,K$4:K$30) -> 1
O27: =IFERROR(K25/SUM(M25:N27),0) -> 0
A28: =J1 -> #N/A | K28: =5*(COUNTIF(B28:J30,"5/0")+COUNTIF(B28:J30,"4/1")+COUNTIF(B28:J30,"3/2")+COUNTIF(B28:J30,"5/-"))+3*COUNTIF(B28:J30,"2/3")+2*COUNTIF(B28:J30,"1/4")+COUNTIF(B28:J30,"0/5")+0.01*L28+0.0001*(M28) -> 0 | L28: =1*COUNTIF(B28:J30,"5/0")+1*COUNTIF(B28:J30,"4/1")+1*COUNTIF(B28:J30,"3/2")+1*COUNTIF(B28:J30,"5/-")+0*COUNTIF(B28:J30,"2/3")+0*COUNTIF(B28:J30,"1/4")+0*COUNTIF(B28:J30,"0/5") -> 0 | M28: =5*COUNTIF(B28:J30,"5/0")+4*COUNTIF(B28:J30,"4/1")+3*COUNTIF(B28:J30,"3/2")+5*COUNTIF(B28:J30,"5/-")+2*COUNTIF(B28:J30,"2/3")+1*COUNTIF(B28:J30,"1/4")+0*COUNTIF(B28:J30,"0/5") -> 0 | N28: =0*COUNTIF(B28:J30,"5/0")+1*COUNTIF(B28:J30,"4/1")+2*COUNTIF(B28:J30,"3/2")+3*COUNTIF(B28:J30,"2/3")+4*COUNTIF(B28:J30,"1/4")+5*COUNTIF(B28:J30,"0/5")+5*COUNTIF(B28:J30,"-/5") -> 0 | O28: =RANK(K28,K$4:K$30) -> 1
O30: =IFERROR(K28/SUM(M28:N30),0) -> 0

Sheet G liga
B1: =VLOOKUP(CONCATENATE(LEFT($A$2,1),COLUMN()-1),nevezettek,3,FALSE) -> 0 | C1: =VLOOKUP(CONCATENATE(LEFT($A$2,1),COLUMN()-1),nevezettek,3,FALSE) -> 0 | D1: =VLOOKUP(CONCATENATE(LEFT($A$2,1),COLUMN()-1),nevezettek,3,FALSE) -> 0 | E1: =VLOOKUP(CONCATENATE(LEFT($A$2,1),COLUMN()-1),nevezettek,3,FALSE) -> 0 | F1: =VLOOKUP(CONCATENATE(LEFT($A$2,1),COLUMN()-1),nevezettek,3,FALSE) -> 0 | G1: =VLOOKUP(CONCATENATE(LEFT($A$2,1),COLUMN()-1),nevezettek,3,FALSE) -> 0 | H1: =VLOOKUP(CONCATENATE(LEFT($A$2,1),COLUMN()-1),nevezettek,3,FALSE) -> 0 | I1: =VLOOKUP(CONCATENATE(LEFT($A$2,1),COLUMN()-1),nevezettek,3,FALSE) -> 0 | J1: =VLOOKUP(CONCATENATE(LEFT($A$2,1),COLUMN()-1),nevezettek,3,FALSE) -> #N/A | K1: összpont-szám | L1: Győze-lem | M1: Nyert szett | N1: Vesztett szett | O1: helyezés (hatékonyság)
A2: =RIGHT(CELL("filename",A1),6) -> G liga
A3: =COUNTIF(Ligabeosztas!D:D,LEFT(A2,1)) -> 0
A4: =B1 -> 0 | K4: =5*(COUNTIF(B4:J6,"5/0")+COUNTIF(B4:J6,"4/1")+COUNTIF(B4:J6,"3/2")+COUNTIF(B4:J6,"5/-"))+3*COUNTIF(B4:J6,"2/3")+2*COUNTIF(B4:J6,"1/4")+COUNTIF(B4:J6,"0/5")+0.01*L4+0.0001*(M4) -> 0 | L4: =1*COUNTIF(B4:J6,"5/0")+1*COUNTIF(B4:J6,"4/1")+1*COUNTIF(B4:J6,"3/2")+1*COUNTIF(B4:J6,"5/-")+0*COUNTIF(B4:J6,"2/3")+0*COUNTIF(B4:J6,"1/4")+0*COUNTIF(B4:J6,"0/5") -> 0 | M4: =5*COUNTIF(B4:J6,"5/0")+4*COUNTIF(B4:J6,"4/1")+3*COUNTIF(B4:J6,"3/2")+5*COUNTIF(B4:J6,"5/-")+2*COUNTIF(B4:J6,"2/3")+1*COUNTIF(B4:J6,"1/4")+0*COUNTIF(B4:J6,"0/5") -> 0 | N4: =0*COUNTIF(B4:J6,"5/0")+1*COUNTIF(B4:J6,"4/1")+2*COUNTIF(B4:J6,"3/2")+3*COUNTIF(B4:J6,"2/3")+4*COUNTIF(B4:J6,"1/4")+5*COUNTIF(B4:J6,"0/5")+5*COUNTIF(B4:J6,"-/5") -> 0 | O4: =RANK(K4,K$4:K$30) -> 1
O6: =IFERROR(K4/SUM(M4:N6),0) -> 0
A7: =C1 -> 0 | K7: =5*(COUNTIF(B7:J9,"5/0")+COUNTIF(B7:J9,"4/1")+COUNTIF(B7:J9,"3/2")+COUNTIF(B7:J9,"5/-"))+3*COUNTIF(B7:J9,"2/3")+2*COUNTIF(B7:J9,"1/4")+COUNTIF(B7:J9,"0/5")+0.01*L7+0.0001*(M7) -> 0 | L7: =1*COUNTIF(B7:J9,"5/0")+1*COUNTIF(B7:J9,"4/1")+1*COUNTIF(B7:J9,"3/2")+1*COUNTIF(B7:J9,"5/-")+0*COUNTIF(B7:J9,"2/3")+0*COUNTIF(B7:J9,"1/4")+0*COUNTIF(B7:J9,"0/5") -> 0 | M7: =5*COUNTIF(B7:J9,"5/0")+4*COUNTIF(B7:J9,"4/1")+3*COUNTIF(B7:J9,"3/2")+5*COUNTIF(B7:J9,"5/-")+2*COUNTIF(B7:J9,"2/3")+1*COUNTIF(B7:J9,"1/4")+0*COUNTIF(B7:J9,"0/5") -> 0 | N7: =0*COUNTIF(B7:J9,"5/0")+1*COUNTIF(B7:J9,"4/1")+2*COUNTIF(B7:J9,"3/2")+3*COUNTIF(B7:J9,"2/3")+4*COUNTIF(B7:J9,"1/4")+5*COUNTIF(B7:J9,"0/5")+5*COUNTIF(B7:J9,"-/5") -> 0 | O7: =RANK(K7,K$4:K$30) -> 1
O9: =IFERROR(K7/SUM(M7:N9),0) -> 0
